Workbook

Sheet Tong hop
A2: UVG – Hồ sơ cần kế toán làm rõ
A3: Cập nhật | B3: 46306
A4: Mỗi dòng là một hồ sơ/chuỗi. 29 hồ sơ cần phản hồi, liên quan 53 hóa đơn.
A5: Đủ trường phản hồi nghĩa là đã điền 4 mục chính; chưa đồng nghĩa đã xử lý hoặc nhập hóa đơn.
A7: Nhóm vấn đề | B7: Sheet chi tiết | C7: Hồ sơ | D7: Chưa phản hồi | E7: Cần bổ sung | F7: Đủ trường phản hồi | G7: Việc cần kế toán chốt
A8: Lệch tiền hàng, thuế và thanh toán | B8: Lech tien | C8: =COUNTA('Lech tien'!A8:A15) -> 8 | D8: =COUNTIFS('Lech tien'!R8:R15,"Chưa phản hồi") -> 0 | E8: =COUNTIFS('Lech tien'!R8:R15,"Cần bổ sung") -> 0 | F8: =COUNTIFS('Lech tien'!R8:R15,"Đủ trường phản hồi") -> 8 | G8: Chốt ba khoản tiền đúng, nguyên nhân chênh và hướng xử lý.
A9: Số lượng bằng 0 hoặc để trống | B9: So luong can kiem | C9: =COUNTA('So luong can kiem'!A8:A15) -> 8 | D9: =COUNTIFS('So luong can kiem'!N8:N15,"Chưa phản hồi") -> 0 | E9: =COUNTIFS('So luong can kiem'!N8:N15,"Cần bổ sung") -> 8 | F9: =COUNTIFS('So luong can kiem'!N8:N15,"Đủ trường phản hồi") -> 0 | G9: Phân biệt dòng hàng và dòng diễn giải. Chốt số lượng, tính chất dòng.
A10: Thanh toán gốc để trống | B10: Thanh toan trong | C10: =COUNTA('Thanh toan trong'!A8:A9) -> 2 | D10: =COUNTIFS('Thanh toan trong'!N8:N9,"Chưa phản hồi") -> 0 | E10: =COUNTIFS('Thanh toan trong'!N8:N9,"Cần bổ sung") -> 2 | F10: =COUNTIFS('Thanh toan trong'!N8:N9,"Đủ trường phản hồi") -> 0 | G10: Xác nhận thanh toán gốc bằng 0 hay đang thiếu số liệu.
A11: Khác loại hàng hoặc mô tả | B11: Hang va mo ta | C11: =COUNTA('Hang va mo ta'!A8:A12) -> 5 | D11: =COUNTIFS('Hang va mo ta'!N8:N12,"Chưa phản hồi") -> 0 | E11: =COUNTIFS('Hang va mo ta'!N8:N12,"Cần bổ sung") -> 5 | F11: =COUNTIFS('Hang va mo ta'!N8:N12,"Đủ trường phản hồi") -> 0 | G11: Xác định hàng thực tế, mã hàng và cách xử lý nội dung điều chỉnh.
A12: Cách ghi số lượng và giá trị điều chỉnh | B12: Cach ghi dieu chinh | C12: =COUNTA('Cach ghi dieu chinh'!A8:A13) -> 6 | D12: =COUNTIFS('Cach ghi dieu chinh'!N8:N13,"Chưa phản hồi") -> 0 | E12: =COUNTIFS('Cach ghi dieu chinh'!N8:N13,"Cần bổ sung") -> 6 | F12: =COUNTIFS('Cach ghi dieu chinh'!N8:N13,"Đủ trường phản hồi") -> 0 | G12: Chốt giảm giá, giảm số lượng hay giảm một khoản tổng.
A14: Tổng cần phản hồi | C14: =SUM(C8:C12) -> 29 | D14: =SUM(D8:D12) -> 0 | E14: =SUM(E8:E12) -> 21 | F14: =SUM(F8:F12) -> 8
A17: Phạm vi bổ sung
A18: Đã đưa thêm 6 hóa đơn chưa điều chỉnh có dòng SL 0 đang được giữ ngoài import vào nhóm số lượng.
A20: Đã có căn cứ/quy ước
A21: 7 hồ sơ ở sheet Da co can cu được giữ riêng để không hỏi lại thông tin hoặc quyết định đã có.
A23: Phạm vi đợt này
A24: Các chuỗi thay thế chưa được mở xử lý trong đợt điều chỉnh này. File này tổng hợp các vấn đề đang chờ đã xác định.

Sheet Lech tien
A2: Lệch tiền hàng, thuế và thanh toán
A3: Cập nhật | B3: 46306
A4: Ô vàng: kế toán điền nguyên nhân, hướng xử lý, số liệu/nội dung đúng và căn cứ.
A5: Số/ngày của mọi hóa đơn trong chuỗi và số tiền nguồn nằm tại sheet Hoa don lien quan.
A7: Mã hồ sơ | B7: Hóa đơn gốc | C7: Ngày gốc | D7: HĐ điều chỉnh liên quan | E7: Ngày điều chỉnh | F7: Tiền hàng XML (đ) | G7: Thuế XML (đ) | H7: Thanh toán XML (đ) | I7: Hàng + thuế − thanh toán (đ) | J7: Ghi nhận cần kiểm tra | K7: Câu hỏi cần kế toán kết luận | L7: Nguyên nhân (KT điền) | M7: Hướng xử lý (KT điền) | N7: Số liệu/nội dung đúng (KT điền) | O7: Căn cứ/chứng từ (KT điền) | P7: Người phản hồi | Q7: Ngày phản hồi | R7: Theo dõi phản hồi
A8: LT01 | B8: 1C25TUV/00000159 | C8: 45716 | D8: 1C25TUV/00000649 | E8: 45782 | F8: -381481 | G8: -30518 | H8: 411999 | I8: =F8+G8-H8 -> -823998 | J8: Tổng tiền trong XML khớp bảng kê nhưng tiền hàng + thuế khác thanh toán. Tiền hàng và thuế âm, thanh toán dương. Thành tiền dòng XML bằng 0 trong khi tổng tiền hàng khác 0. | K8: Xác định tiền hàng, thuế và thanh toán đúng, nguyên nhân chênh, căn cứ và hướng xử lý. Kiểm cả phần dòng và phần tổng. Nếu đã có chứng từ xử lý tiếp, ghi số/ngày. | L8: Do kế toán xuất sai | M8: Xuất trái dấu ở tất cả các chỉ tiêu | N8: - Tiền hàng: -381,481 - Tiền thuế: -30,518 - Thanh toán: -411,999 | O8: Không có, tính lại cho đúng logic số liệu | P8: Kế toán | Q8: 46306 | R8: =IF(COUNTA(L8:Q8)=0,"Chưa phản hồi",IF(AND(L8<>"",M8<>"",N8<>"",O8<>""),"Đủ trường phản hồi","Cần bổ sung")) -> Đủ trường phản hồi
A9: LT02 | B9: 1C25TUV/00000056 | C9: 45684 | D9: 1C25TUV/00000561 | E9: 45781 | F9: 196889 | G9: 151751 | H9: 212640 | I9: =F9+G9-H9 -> 136000 | J9: Tổng tiền trong XML khớp bảng kê nhưng tiền hàng + thuế khác thanh toán. Thành tiền dòng XML bằng 0 trong khi tổng tiền hàng khác 0. | K9: Xác định tiền hàng, thuế và thanh toán đúng, nguyên nhân chênh, căn cứ và hướng xử lý. Kiểm cả phần dòng và phần tổng. Nếu đã có chứng từ xử lý tiếp, ghi số/ngày. | L9: Do kế toán xuất sai | M9: Xuất trái dấu ở tất cả các chỉ tiêu | N9: - Tiền hàng: 196,889 - Tiền thuế: 15,751 - Thanh toán: 212,640 | O9: Không có, tính lại cho đúng logic số liệu | P9: Kế toán | Q9: 46306 | R9: =IF(COUNTA(L9:Q9)=0,"Chưa phản hồi",IF(AND(L9<>"",M9<>"",N9<>"",O9<>""),"Đủ trường phản hồi","Cần bổ sung")) -> Đủ trường phản hồi
A10: LT03 | B10: 1C24TUV/00000283 | C10: 45457 | D10: 1C25TUV/00001819 | E10: 45806 | F10: 7599678 | G10: 609974 | H10: 8207652 | I10: =F10+G10-H10 -> 2000 | J10: Tổng tiền trong XML khớp bảng kê nhưng tiền hàng + thuế khác thanh toán. Thành tiền dòng XML bằng 0 trong khi tổng tiền hàng khác 0. | K10: Xác định tiền hàng, thuế và thanh toán đúng, nguyên nhân chênh, căn cứ và hướng xử lý. Kiểm cả phần dòng và phần tổng. Nếu đã có chứng từ xử lý tiếp, ghi số/ngày. | L10: Do kế toán xuất sai | M10: Xuất trái dấu ở tất cả các chỉ tiêu | N10: - Tiền hàng: 7,599,678 - Tiền thuế: 609,974 - Thanh toán: 8,209,652 | O10: Không có, tính lại cho đúng logic số liệu | P10: Kế toán | Q10: 46306 | R10: =IF(COUNTA(L10:Q10)=0,"Chưa phản hồi",IF(AND(L10<>"",M10<>"",N10<>"",O10<>""),"Đủ trường phản hồi","Cần bổ sung")) -> Đủ trường phản hồi
A11: LT04 | B11: 1C24TUV/00000093 | C11: 45352 | D11: 1C25TUV/00001167 | E11: 45803 | F11: 621945 | G11: 49756 | H11: 670701 | I11: =F11+G11-H11 -> 1000 | J11: Tổng tiền trong XML khớp bảng kê nhưng tiền hàng + thuế khác thanh toán. Thành tiền dòng XML bằng 0 trong khi tổng tiền hàng khác 0. | K11: Xác định tiền hàng, thuế và thanh toán đúng, nguyên nhân chênh, căn cứ và hướng xử lý. Kiểm cả phần dòng và phần tổng. Nếu đã có chứng từ xử lý tiếp, ghi số/ngày. | L11: Do kế toán xuất sai | M11: Xuất trái dấu ở tất cả các chỉ tiêu | N11: - Tiền hàng: 621,945 - Tiền thuế: 49,756 - Thanh toán: 671,701 | O11: Không có, tính lại cho đúng logic số liệu | P11: Kế toán | Q11: 46306 | R11: =IF(COUNTA(L11:Q11)=0,"Chưa phản hồi",IF(AND(L11<>"",M11<>"",N11<>"",O11<>""),"Đủ trường phản hồi","Cần bổ sung")) -> Đủ trường phản hồi
A12: LT05 | B12: 1C24TUV/00000535 | C12: 45587 | D12: 1C25TUV/00002145 | E12: 45807 | F12: 39194352 | G12: 3135548 | H12: 42329000 | I12: =F12+G12-H12 -> 900 | J12: Tổng tiền trong XML khớp bảng kê nhưng tiền hàng + thuế khác thanh toán. Thành tiền dòng XML bằng 0 trong khi tổng tiền hàng khác 0. | K12: Xác định tiền hàng, thuế và thanh toán đúng, nguyên nhân chênh, căn cứ và hướng xử lý. Kiểm cả phần dòng và phần tổng. Nếu đã có chứng từ xử lý tiếp, ghi số/ngày. | L12: Do kế toán xuất sai | M12: Xuất trái dấu ở tất cả các chỉ tiêu | N12: - Tiền hàng: 39,194,352 - Tiền thuế: 3,135,548 - Thanh toán: 42,329,900 | O12: Không có, tính lại cho đúng logic số liệu | P12: Kế toán | Q12: 46306 | R12: =IF(COUNTA(L12:Q12)=0,"Chưa phản hồi",IF(AND(L12<>"",M12<>"",N12<>"",O12<>""),"Đủ trường phản hồi","Cần bổ sung")) -> Đủ trường phản hồi
A13: LT06 | B13: 1C24TUV/00000228 | C13: 45425 | D13: 1C25TUV/00002619 | E13: 45808 | F13: -589554 | G13: -47164 | H13: -636719 | I13: =F13+G13-H13 -> 1 | J13: Tổng tiền trong XML khớp bảng kê nhưng tiền hàng + thuế khác thanh toán. Thành tiền dòng XML bằng 0 trong khi tổng tiền hàng khác 0. Chuỗi còn điều chỉnh 1C25TUV/00002646 ngày 31/05/2025; xem Hoa don lien quan. | K13: Xác định tiền hàng, thuế và thanh toán đúng, nguyên nhân chênh, căn cứ và hướng xử lý. Kiểm cả phần dòng và phần tổng. Nếu đã có chứng từ xử lý tiếp, ghi số/ngày. | L13: Do kế toán xuất sai | M13: Xuất trái dấu ở tất cả các chỉ tiêu | N13: - Tiền hàng: -589,554 - Tiền thuế: -47,164 - Thanh toán: -636,718 | O13: Không có, tính lại cho đúng logic số liệu | P13: Kế toán | Q13: 46306 | R13: =IF(COUNTA(L13:Q13)=0,"Chưa phản hồi",IF(AND(L13<>"",M13<>"",N13<>"",O13<>""),"Đủ trường phản hồi","Cần bổ sung")) -> Đủ trường phản hồi
A14: LT07 | B14: 1C24TUV/00000285 | C14: 45458 | D14: 1C25TUV/00001821 | E14: 45806 | F14: 5701066 | G14: 456085 | H14: 6157152 | I14: =F14+G14-H14 -> -1 | J14: Tổng tiền trong XML khớp bảng kê nhưng tiền hàng + thuế khác thanh toán. Thành tiền dòng XML bằng 0 trong khi tổng tiền hàng khác 0. | K14: Xác định tiền hàng, thuế và thanh toán đúng, nguyên nhân chênh, căn cứ và hướng xử lý. Kiểm cả phần dòng và phần tổng. Nếu đã có chứng từ xử lý tiếp, ghi số/ngày. | L14: Do kế toán xuất sai | M14: Xuất trái dấu ở tất cả các chỉ tiêu | N14: - Tiền hàng: 5,701,066 - Tiền thuế: 456,085 - Thanh toán: 6,157,151 | O14: Không có, tính lại cho đúng logic số liệu | P14: Kế toán | Q14: 46306 | R14: =IF(COUNTA(L14:Q14)=0,"Chưa phản hồi",IF(AND(L14<>"",M14<>"",N14<>"",O14<>""),"Đủ trường phản hồi","Cần bổ sung")) -> Đủ trường phản hồi
A15: LT08 | B15: 1C25TUV/00000102 | C15: 45707 | D15: 1C25TUV/00000626 | E15: 45781 | F15: 4347265 | G15: 347781 | H15: 4695045 | I15: =F15+G15-H15 -> 1 | J15: Tổng tiền trong XML khớp bảng kê nhưng tiền hàng + thuế khác thanh toán. Thành tiền dòng XML bằng 0 trong khi tổng tiền hàng khác 0. | K15: Xác định tiền hàng, thuế và thanh toán đúng, nguyên nhân chênh, căn cứ và hướng xử lý. Kiểm cả phần dòng và phần tổng. Nếu đã có chứng từ xử lý tiếp, ghi số/ngày. | L15: Do kế toán xuất sai | M15: Xuất trái dấu ở tất cả các chỉ tiêu | N15: - Tiền hàng: 4,347,265 - Tiền thuế: 347,781 - Thanh toán: 4,695,046 | O15: Không có, tính lại cho đúng logic số liệu | P15: Kế toán | Q15: 46306 | R15: =IF(COUNTA(L15:Q15)=0,"Chưa phản hồi",IF(AND(L15<>"",M15<>"",N15<>"",O15<>""),"Đủ trường phản hồi","Cần bổ sung")) -> Đủ trường phản hồi

Sheet So luong can kiem
A2: Số lượng bằng 0 hoặc để trống
A3: Cập nhật | B3: 46306
A4: Ô vàng: kế toán điền nguyên nhân, hướng xử lý, số liệu/nội dung đúng và căn cứ.
A5: Số/ngày của mọi hóa đơn trong chuỗi và số tiền nguồn nằm tại sheet Hoa don lien quan.
A7: Mã hồ sơ | B7: Hóa đơn gốc | C7: Ngày gốc | D7: HĐ điều chỉnh liên quan | E7: Ngày điều chỉnh | F7: Ghi nhận cần kiểm tra | G7: Câu hỏi cần kế toán kết luận | H7: Nguyên nhân (KT điền) | I7: Hướng xử lý (KT điền) | J7: Số liệu/nội dung đúng (KT điền) | K7: Căn cứ/chứng từ (KT điền) | L7: Người phản hồi | M7: Ngày phản hồi | N7: Theo dõi phản hồi
A8: SL01 | B8: 1C24TUV/00000555 | C8: 45596 | D8: 1C25TUV/00002632 | E8: 45808 | F8: Dòng màng lọc HEPA H13 KA350 FT (BS HĐ 547): số lượng và đơn giá trống. Tiền hàng 46.296, thuế 3.705, thanh toán dòng 50.001. Hóa đơn gốc có 6 dòng. | G8: Đối chiếu đúng dòng hàng trên XML gốc/bản hiển thị hoặc chứng từ bán. Chốt số lượng, đơn giá, tiền dòng và đây là hàng bán, khuyến mãi hay diễn giải. Ghi nguyên nhân thiếu số liệu và hướng chuẩn bị phần giảm chi tiết. | H8: Kế toán xuất sai | I8: Giữ nguyên dòng số 6 "Màng Lọc HEPA H13 Diệt Khuẩn Cho Máy Lọc Không Khí UVGREEN KA350 FT ( BS HĐ 547)" diễn giải, xuất điều chỉnh âm số lượng dòng đó | J8: Dòng 6 "Màng Lọc HEPA H13 Diệt Khuẩn Cho Máy Lọc Không Khí UVGREEN KA350 FT ( BS HĐ 547)" điều chỉnh giảm Thành tiền chưa có thuế GTGT: -46,296 | L8: Kế toán | M8: 46306 | N8: =IF(COUNTA(H8:M8)=0,"Chưa phản hồi",IF(AND(H8<>"",I8<>"",J8<>"",K8<>""),"Đủ trường phản hồi","Cần bổ sung")) -> Cần bổ sung
A9: SL02 | B9: 1C25TUV/00000113 | C9: 45707 | D9: 1C25TUV/00000635 | E9: 45782 | F9: Dòng màng/lõi lọc HEPA H13 KA600 FT: số lượng, đơn giá và tiền dòng trống trong bảng xuất mới. Hóa đơn gốc có 48 dòng. Không tự coi các ô trống là 0. | G9: Đối chiếu đúng dòng hàng trên XML gốc/bản hiển thị hoặc chứng từ bán. Chốt số lượng, đơn giá, tiền dòng và đây là hàng bán, khuyến mãi hay diễn giải. Ghi nguyên nhân thiếu số liệu và hướng chuẩn bị phần giảm chi tiết. | H9: Kế toán xuất sai | I9: Bỏ dòng số 45 "Màng Lọc (Lõi Lọc) HEPA H13 Diệt Khuẩn Cho Máy Lọc Không Khí UVGREEN KA600 FT" đi do số lượng, đơn giá, thành tiền bằng 0. | J9: Bỏ dòng số 45 "Màng Lọc (Lõi Lọc) HEPA H13 Diệt Khuẩn Cho Máy Lọc Không Khí UVGREEN KA600 FT" đi do số lượng, đơn giá, thành tiền bằng 0. | L9: Kế toán | M9: 46306 | N9: =IF(COUNTA(H9:M9)=0,"Chưa phản hồi",IF(AND(H9<>"",I9<>"",J9<>"",K9<>""),"Đủ trường phản hồi","Cần bổ sung")) -> Cần bổ sung
A10: SL03 | B10: 1C24TUV/00000774 | C10: 45657 | F10: Nhóm chưa điều chỉnh. Toàn bộ 2 dòng đã được giữ ngoài import vì dòng “( Hàng biếu, tặng không thu tiền)” lưu SL/đơn giá/thành tiền = 0 ở bảng kiểm. Bảng xuất mới: SL trống, đơn giá trống, thành tiền trống. | G10: Xác nhận dòng này là chú thích hàng tặng hay một mặt hàng có số lượng thực tế. Chốt tính chất và số lượng cần thể hiện khi chuẩn bị điều chỉnh toàn bộ hóa đơn. Không tự bỏ dòng hoặc đưa lại vào import. | H10: Đây là dòng có tính chất là "Ghi chú, diễn giải" để diễn giải nội dung là "Hàng biếu, tặng không thu tiền" => đúng rồi. | I10: Đây là dòng chú thích hàng tặng, giữ nguyên, không được bỏ dòng này. Vẫn giữ lại khi xuất hóa đơn điều chỉnh. | J10: Đây là dòng chú thích hàng tặng, giữ nguyên, không được bỏ dòng này. Vẫn giữ lại khi xuất hóa đơn điều chỉnh. | L10: Kế toán | M10: 46306 | N10: =IF(COUNTA(H10:M10)=0,"Chưa phản hồi",IF(AND(H10<>"",I10<>"",J10<>"",K10<>""),"Đủ trường phản hồi","Cần bổ sung")) -> Cần bổ sung
A11: SL04 | B11: 1C24TUV/00000783 | C11: 45657 | F11: Nhóm chưa điều chỉnh. Toàn bộ 3 dòng đã được giữ ngoài import vì dòng “( Hàng tặng không thu tiền)” lưu SL/đơn giá/thành tiền = 0 ở bảng kiểm. Bảng xuất mới: SL trống, đơn giá trống, thành tiền trống. | G11: Xác nhận dòng này là chú thích hàng tặng hay một mặt hàng có số lượng thực tế. Chốt tính chất và số lượng cần thể hiện khi chuẩn bị điều chỉnh toàn bộ hóa đơn. Không tự bỏ dòng hoặc đưa lại vào import. | H11: Đây là dòng có tính chất là "Ghi chú, diễn giải" để diễn giải nội dung là "Hàng biếu, tặng không thu tiền" => đúng rồi. | I11: Đây là dòng chú thích hàng tặng, giữ nguyên, không được bỏ dòng này. Vẫn giữ lại khi xuất hóa đơn điều chỉnh. | J11: Đây là dòng chú thích hàng tặng, giữ nguyên, không được bỏ dòng này. Vẫn giữ lại khi xuất hóa đơn điều chỉnh. | L11: Kế toán | M11: 46306 | N11: =IF(COUNTA(H11:M11)=0,"Chưa phản hồi",IF(AND(H11<>"",I11<>"",J11<>"",K11<>""),"Đủ trường phản hồi","Cần bổ sung")) -> Cần bổ sung
A12: SL05 | B12: 1C24TUV/00000784 | C12: 45657 | F12: Nhóm chưa điều chỉnh. Toàn bộ 3 dòng đã được giữ ngoài import vì dòng “( Hàng tặng không thu tiền)” lưu SL/đơn giá/thành tiền = 0 ở bảng kiểm. Bảng xuất mới: SL trống, đơn giá trống, thành tiền trống. | G12: Xác nhận dòng này là chú thích hàng tặng hay một mặt hàng có số lượng thực tế. Chốt tính chất và số lượng cần thể hiện khi chuẩn bị điều chỉnh toàn bộ hóa đơn. Không tự bỏ dòng hoặc đưa lại vào import. | H12: Đây là dòng có tính chất là "Ghi chú, diễn giải" để diễn giải nội dung là "Hàng biếu, tặng không thu tiền" => đúng rồi. | I12: Đây là dòng chú thích hàng tặng, giữ nguyên, không được bỏ dòng này. Vẫn giữ lại khi xuất hóa đơn điều chỉnh. | J12: Đây là dòng chú thích hàng tặng, giữ nguyên, không được bỏ dòng này. Vẫn giữ lại khi xuất hóa đơn điều chỉnh. | L12: Kế toán | M12: 46306 | N12: =IF(COUNTA(H12:M12)=0,"Chưa phản hồi",IF(AND(H12<>"",I12<>"",J12<>"",K12<>""),"Đủ trường phản hồi","Cần bổ sung")) -> Cần bổ sung
A13: SL06 | B13: 1C24TUV/00000786 | C13: 45657 | F13: Nhóm chưa điều chỉnh. Toàn bộ 15 dòng đã được giữ ngoài import vì dòng “( hàng tặng không thu tiền)” lưu SL/đơn giá/thành tiền = 0 ở bảng kiểm. Bảng xuất mới: SL trống, đơn giá trống, thành tiền trống. | G13: Xác nhận dòng này là chú thích hàng tặng hay một mặt hàng có số lượng thực tế. Chốt tính chất và số lượng cần thể hiện khi chuẩn bị điều chỉnh toàn bộ hóa đơn. Không tự bỏ dòng hoặc đưa lại vào import. | H13: Đây là dòng có tính chất là "Ghi chú, diễn giải" để diễn giải nội dung là "Hàng biếu, tặng không thu tiền" => đúng rồi. | I13: Đây là dòng chú thích hàng tặng, giữ nguyên, không được bỏ dòng này. Vẫn giữ lại khi xuất hóa đơn điều chỉnh. | J13: Đây là dòng chú thích hàng tặng, giữ nguyên, không được bỏ dòng này. Vẫn giữ lại khi xuất hóa đơn điều chỉnh. | L13: Kế toán | M13: 46306 | N13: =IF(COUNTA(H13:M13)=0,"Chưa phản hồi",IF(AND(H13<>"",I13<>"",J13<>"",K13<>""),"Đủ trường phản hồi","Cần bổ sung")) -> Cần bổ sung
A14: SL07 | B14: 1C25TUV/00002796 | C14: 45809 | F14: Nhóm chưa điều chỉnh. Toàn bộ 2 dòng đã được giữ ngoài import vì dòng “Vợt bắt muỗi tự động 2 trong 1 thu hút các loại côn trùng KM002” lưu SL/đơn giá/thành tiền = 0 ở bảng kiểm. Bảng xuất mới: SL trống, đơn giá trống, thành tiền trống. | G14: Đối chiếu mặt hàng tặng KM002/KM003 với chứng từ bán hoặc XML gốc. Chốt số lượng thực tế và tính chất dòng, giải thích vì sao SL/đơn giá/thành tiền bằng 0. Xác định cách thể hiện khi chuẩn bị điều chỉnh. | H14: Kế toán xuất sai | I14: Bỏ dòng số 2 "Vợt bắt muỗi tự động 2 trong 1 thu hút các loại côn trùng KM002" đi do số lượng, đơn giá, thành tiền bằng 0. | J14: Bỏ dòng số 2 "Vợt bắt muỗi tự động 2 trong 1 thu hút các loại côn trùng KM002" đi do số lượng, đơn giá, thành tiền bằng 0. | L14: Kế toán | M14: 46306 | N14: =IF(COUNTA(H14:M14)=0,"Chưa phản hồi",IF(AND(H14<>"",I14<>"",J14<>"",K14<>""),"Đủ trường phản hồi","Cần bổ sung")) -> Cần bổ sung
A15: SL08 | B15: 1C25TUV/00002797 | C15: 45809 | F15: Nhóm chưa điều chỉnh. Toàn bộ 2 dòng đã được giữ ngoài import vì dòng “Vợt bắt muỗi tự động 2 trong 1 thu hút các loại côn trùng KM003” lưu SL/đơn giá/thành tiền = 0 ở bảng kiểm. Bảng xuất mới: SL trống, đơn giá trống, thành tiền trống. | G15: Đối chiếu mặt hàng tặng KM002/KM003 với chứng từ bán hoặc XML gốc. Chốt số lượng thực tế và tính chất dòng, giải thích vì sao SL/đơn giá/thành tiền bằng 0. Xác định cách thể hiện khi chuẩn bị điều chỉnh. | H15: Kế toán xuất sai | I15: Bỏ dòng số 2 "Vợt bắt muỗi tự động 2 trong 1 thu hút các loại côn trùng KM002" đi do số lượng, đơn giá, thành tiền bằng 0. | J15: Bỏ dòng số 2 "Vợt bắt muỗi tự động 2 trong 1 thu hút các loại côn trùng KM002" đi do số lượng, đơn giá, thành tiền bằng 0. | L15: Kế toán | M15: 46306 | N15: =IF(COUNTA(H15:M15)=0,"Chưa phản hồi",IF(AND(H15<>"",I15<>"",J15<>"",K15<>""),"Đủ trường phản hồi","Cần bổ sung")) -> Cần bổ sung

Sheet Thanh toan trong
A2: Thanh toán gốc để trống
A3: Cập nhật | B3: 46306
A4: Ô vàng: kế toán điền nguyên nhân, hướng xử lý, số liệu/nội dung đúng và căn cứ.
A5: Số/ngày của mọi hóa đơn trong chuỗi và số tiền nguồn nằm tại sheet Hoa don lien quan.
A7: Mã hồ sơ | B7: Hóa đơn gốc | C7: Ngày gốc | D7: HĐ điều chỉnh liên quan | E7: Ngày điều chỉnh | F7: Ghi nhận cần kiểm tra | G7: Câu hỏi cần kế toán kết luận | H7: Nguyên nhân (KT điền) | I7: Hướng xử lý (KT điền) | J7: Số liệu/nội dung đúng (KT điền) | K7: Căn cứ/chứng từ (KT điền) | L7: Người phản hồi | M7: Ngày phản hồi | N7: Theo dõi phản hồi
A8: TT01 | B8: 1C25TUV/00000006 | C8: 45664 | D8: 1C25TUV/00000655 | E8: 45782 | F8: Bảng tổng của hóa đơn gốc ghi tiền hàng = 0, thuế = 0 nhưng thanh toán để trống. Chưa có XML gốc trong phần nguồn đã lưu hiện tại để xác nhận giá trị thanh toán. Điều chỉnh liên quan đã có XML. | G8: Thanh toán gốc đúng là 0 hay bảng xuất đang thiếu? Nếu thiếu, chốt giá trị đúng và căn cứ. Nếu đúng 0, xác nhận rõ cho riêng hóa đơn này. Không áp dụng quy ước của gốc 1C24TUV/00000574 sang đây. | H8: Kế toán xuất sai | I8: Xuất âm số lượng các dòng hàng hóa trên hóa đơn | J8: Dòng 1 "Máy Lọc Không Khí Diệt Khuẩn UVGREEN KA350 UVC PRO 40m2": Số lượng: -1 Dòng 2 "Màng Lọc HEPA H13 Diệt Khuẩn Cho Máy Lọc Không Khí UVGREEN KA350 FT": số lượng -1 Dòng 3 "Máy Lọc Không Khí Diệt Khuẩn UVGREEN KA150S-UVC LED": số lượng: -1 Dòng 4 "Máy Lọc Không Khí Diệt Khuẩn UVGREEN KA150P-UVC LED": số lượng: -1 Dòng 5 "Máy Lọc Không Khí Diệt Khuẩn UVGREEN KA150S-UVC LED": số lượng: -1 | L8: Kế toán | M8: 46306 | N8: =IF(COUNTA(H8:M8)=0,"Chưa phản hồi",IF(AND(H8<>"",I8<>"",J8<>"",K8<>""),"Đủ trường phản hồi","Cần bổ sung")) -> Cần bổ sung
A9: TT02 | B9: 1C25TUV/00000016 | C9: 45671 | D9: 1C25TUV/00000657 | E9: 45782 | F9: Bảng tổng của hóa đơn gốc ghi tiền hàng = 0, thuế = 0 nhưng thanh toán để trống. Chưa có XML gốc trong phần nguồn đã lưu hiện tại để xác nhận giá trị thanh toán. Điều chỉnh liên quan đã có XML. | G9: Thanh toán gốc đúng là 0 hay bảng xuất đang thiếu? Nếu thiếu, chốt giá trị đúng và căn cứ. Nếu đúng 0, xác nhận rõ cho riêng hóa đơn này. Không áp dụng quy ước của gốc 1C24TUV/00000574 sang đây. | H9: Kế toán xuất sai | I9: Xuất âm số lượng các dòng hàng hóa trên hóa đơn | J9: Dòng 1 "Máy Lọc Không Khí Diệt Khuẩn UVGREEN KA150-UVC LED": số lượng: -1 Dòng 2 "Máy Lọc Không Khí Diệt Khuẩn UVGREEN KA150-UVC LED": số lượng: -1 Dòng 3 "Máy Lọc Không Khí Diệt Khuẩn UVC LED UVGREEN KA600 60m2": số lượng: -1 | L9: Kế toán | M9: 46306 | N9: =IF(COUNTA(H9:M9)=0,"Chưa phản hồi",IF(AND(H9<>"",I9<>"",J9<>"",K9<>""),"Đủ trường phản hồi","Cần bổ sung")) -> Cần bổ sung

Sheet Hang va mo ta
A2: Khác loại hàng hoặc mô tả
A3: Cập nhật | B3: 46306
A4: Ô vàng: kế toán điền nguyên nhân, hướng xử lý, số liệu/nội dung đúng và căn cứ.
A5: Số/ngày của mọi hóa đơn trong chuỗi và số tiền nguồn nằm tại sheet Hoa don lien quan.
A7: Mã hồ sơ | B7: Hóa đơn gốc | C7: Ngày gốc | D7: HĐ điều chỉnh liên quan | E7: Ngày điều chỉnh | F7: Ghi nhận cần kiểm tra | G7: Câu hỏi cần kế toán kết luận | H7: Nguyên nhân (KT điền) | I7: Hướng xử lý (KT điền) | J7: Số liệu/nội dung đúng (KT điền) | K7: Căn cứ/chứng từ (KT điền) | L7: Người phản hồi | M7: Ngày phản hồi | N7: Theo dõi phản hồi
A8: HH01 | B8: 1C25TUV/00003548 | C8: 45814 | D8: 1C25TUV/00013072 | E8: 45930 | F8: Khác loại hàng. Gốc: Máy lọc không khí diệt khuẩn bằng tia UVC KA150S. Điều chỉnh: Lõi lọc diệt khuẩn - Filter - KA150S. Cộng dồn tiền hàng, thuế, thanh toán đã bằng 0. | G8: Xác định hàng thực tế bán/trả, tên và mã hàng đúng. Bên nào ghi sai giữa gốc và điều chỉnh? Chốt hướng xử lý lần điều chỉnh cũ và dữ liệu cần chuẩn bị tiếp. | H8: Kế toán xuất sai | I8: Hóa đơn Điều chỉnh cho hóa đơn 13072 tăng số lượng của "Lõi lọc diệt khuẩn - Filter - KA150S" Hóa đơn Điều chỉnh cho hóa đơn 3548 giảm số lượng của "Máy lọc không khí diệt khuẩn bằng tia UVC KA150S" | J8: Hóa đơn Điều chỉnh cho hóa đơn 13072 tăng số lượng của "Lõi lọc diệt khuẩn - Filter - KA150S": 1 Hóa đơn Điều chỉnh cho hóa đơn 3548 giảm số lượng của "Máy lọc không khí diệt khuẩn bằng tia UVC KA150S": -1 | N8: =IF(COUNTA(H8:M8)=0,"Chưa phản hồi",IF(AND(H8<>"",I8<>"",J8<>"",K8<>""),"Đủ trường phản hồi","Cần bổ sung")) -> Cần bổ sung
A9: HH02 | B9: 1C25TUV/00004026 | C9: 45816 | D9: 1C25TUV/00013079 | E9: 45930 | F9: Khác mô tả. Gốc: Máy phun sương tạo độ ẩm không khí diệt khuẩn bằng tia UVC KH100. Điều chỉnh: Máy phun sương tạo độ ẩm không khí diệt khuẩn bằng tia UVC với màn hình LCD - KH100. Cộng dồn tiền hàng, thuế, thanh toán đã bằng 0. | G9: Hai mô tả có cùng mã hàng/sản phẩm thực tế không? Xác nhận rõ cùng hàng hoặc chỉ ra khác biệt. Chốt mô tả đúng và hướng xử lý nội dung điều chỉnh. | H9: 2 máy đó thực tế là 1 sản phẩm. | I9: Không cần xử lý xuất lại hóa đơn điều chỉnh nữa | J9: Không cần xử lý xuất lại hóa đơn điều chỉnh nữa | N9: =IF(COUNTA(H9:M9)=0,"Chưa phản hồi",IF(AND(H9<>"",I9<>"",J9<>"",K9<>""),"Đủ trường phản hồi","Cần bổ sung")) -> Cần bổ sung
A10: HH03 | B10: 1C25TUV/00004953 | C10: 45820 | D10: 1C25TUV/00013089 | E10: 45930 | F10: Khác mô tả. Gốc: Máy lọc không khí diệt khuẩn bằng tia UVC KA350 ProUpgrade. Điều chỉnh: Máy lọc không khí diệt khuẩn bằng tia UVC - KA350 Pro-Upgrade. Cộng dồn tiền hàng, thuế, thanh toán đã bằng 0. | G10: Hai mô tả có cùng mã hàng/sản phẩm thực tế không? Xác nhận rõ cùng hàng hoặc chỉ ra khác biệt. Chốt mô tả đúng và hướng xử lý nội dung điều chỉnh. | H10: 2 máy đó thực tế là 1 sản phẩm. | I10: Không cần xử lý xuất lại hóa đơn điều chỉnh nữa | J10: Không cần xử lý xuất lại hóa đơn điều chỉnh nữa | N10: =IF(COUNTA(H10:M10)=0,"Chưa phản hồi",IF(AND(H10<>"",I10<>"",J10<>"",K10<>""),"Đủ trường phản hồi","Cần bổ sung")) -> Cần bổ sung
A11: HH04 | B11: 1C25TUV/00005905 | C11: 45824 | D11: 1C25TUV/00013095 | E11: 45930 | F11: Khác loại hàng. Gốc: Lõi lọc diệt khuẩn Filter KA600. Điều chỉnh: Máy lọc không khí diệt khuẩn bằng tia UVC - KA600. Cộng dồn tiền hàng, thuế, thanh toán đã bằng 0. | G11: Xác định hàng thực tế bán/trả, tên và mã hàng đúng. Bên nào ghi sai giữa gốc và điều chỉnh? Chốt hướng xử lý lần điều chỉnh cũ và dữ liệu cần chuẩn bị tiếp. | H11: Kế toán xuất sai | I11: Hóa đơn Điều chỉnh cho hóa đơn 5905 giảm số lượng của "Lõi lọc diệt khuẩn Filter KA600" Hóa đơn Điều chỉnh cho hóa đơn 13095 tăng số lượng của "Máy lọc không khí diệt khuẩn bằng tia UVC - KA600" | J11: Hóa đơn Điều chỉnh cho hóa đơn 5905 giảm số lượng của "Lõi lọc diệt khuẩn Filter KA600": -1 Hóa đơn Điều chỉnh cho hóa đơn 13095 tăng số lượng của "Máy lọc không khí diệt khuẩn bằng tia UVC - KA600": 1 | N11: =IF(COUNTA(H11:M11)=0,"Chưa phản hồi",IF(AND(H11<>"",I11<>"",J11<>"",K11<>""),"Đủ trường phản hồi","Cần bổ sung")) -> Cần bổ sung
A12: HH05 | B12: 1C25TUV/00007766 | C12: 45830 | D12: 1C25TUV/00013099 | E12: 45930 | F12: Khác mô tả. Gốc: Máy phun sương tạo độ ẩm không khí diệt khuẩn bằng tia UVC KH100. Điều chỉnh: Máy phun sương tạo độ ẩm không khí diệt khuẩn bằng tia UVC với màn hình LCD - KH100. Cộng dồn tiền hàng, thuế, thanh toán đã bằng 0. | G12: Hai mô tả có cùng mã hàng/sản phẩm thực tế không? Xác nhận rõ cùng hàng hoặc chỉ ra khác biệt. Chốt mô tả đúng và hướng xử lý nội dung điều chỉnh. | H12: 2 máy đó thực tế là 1 sản phẩm. | I12: Không cần xử lý xuất lại hóa đơn điều chỉnh nữa | J12: Không cần xử lý xuất lại hóa đơn điều chỉnh nữa | N12: =IF(COUNTA(H12:M12)=0,"Chưa phản hồi",IF(AND(H12<>"",I12<>"",J12<>"",K12<>""),"Đủ trường phản hồi","Cần bổ sung")) -> Cần bổ sung

Sheet Cach ghi dieu chinh
A2: Cách ghi số lượng và giá trị điều chỉnh
A3: Cập nhật | B3: 46306
A4: Ô vàng: kế toán điền nguyên nhân, hướng xử lý, số liệu/nội dung đúng và căn cứ.
A5: Số/ngày của mọi hóa đơn trong chuỗi và số tiền nguồn nằm tại sheet Hoa don lien quan.
A7: Mã hồ sơ | B7: Hóa đơn gốc | C7: Ngày gốc | D7: HĐ điều chỉnh liên quan | E7: Ngày điều chỉnh | F7: Ghi nhận cần kiểm tra | G7: Câu hỏi cần kế toán kết luận | H7: Nguyên nhân (KT điền) | I7: Hướng xử lý (KT điền) | J7: Số liệu/nội dung đúng (KT điền) | K7: Căn cứ/chứng từ (KT điền) | L7: Người phản hồi | M7: Ngày phản hồi | N7: Theo dõi phản hồi
A8: DC01 | B8: 1C25TUV/00001061 | C8: 45803 | D8: 1C25TUV/00012835 | E8: 45885 | F8: Gốc có 1 đèn bắt muỗi KM300. Điều chỉnh giảm một khoản tổng: SL/đơn giá = 0, thành tiền dòng -499.074, thuế -39.926, thanh toán -539.000. Tiền dòng khớp phần tổng và chuỗi đã về 0. | G8: Nghiệp vụ thực tế là giảm một khoản tiền hay giảm toàn bộ 1 sản phẩm KM300? Chốt cách thể hiện nội dung/số lượng đúng với mục tiêu xử lý tiếp và căn cứ. | H8: Kế toán xuất sai HD 12835. | I8: Hóa đơn điều chỉnh cho HD 1061: giảm toàn bộ 1 sản phẩm KM300: số lượng: -1, đơn giá: 499,074 Hóa đơn điều chỉnh cho HD 12835: tăng lại thành tiền: 499,074, tiền thuế: 39,926, thanh toán: 539,000 | J8: Đèn bắt muỗi, ruồi và các loại côn trùng KM300: số lượng: -1, đơn giá: 499,074, thành tiền: -499,074 | L8: Kế toán | M8: 46306 | N8: =IF(COUNTA(H8:M8)=0,"Chưa phản hồi",IF(AND(H8<>"",I8<>"",J8<>"",K8<>""),"Đủ trường phản hồi","Cần bổ sung")) -> Cần bổ sung
A9: DC02 | B9: 1C25TUV/00001094 | C9: 45803 | D9: 1C25TUV/00013038 | E9: 45926 | F9: Lõi lọc diệt khuẩn Filter KA350S. Hóa đơn gốc SL +1; điều chỉnh vẫn SL +1, đơn giá âm. Tổng tiền đã về 0, số lượng hai phía chưa triệt tiêu. | G9: Nghiệp vụ thực tế là giảm giá hay giảm/trả toàn bộ số lượng hàng? Chốt mục tiêu xử lý số lượng và giá trị, căn cứ và hướng xử lý điều chỉnh cũ. Đơn giá âm chưa tự chứng minh nội dung sai. | H9: Kế toán xuất sai HD 13038 | I9: Hóa đơn điều chỉnh cho HD 1094: giảm toàn bộ 1 Lõi lọc diệt khuẩn Filter KA350S: số lượng: -1, đơn giá: 509,259 Hóa đơn điều chỉnh cho HD 13038: tăng giảm toàn bộ 1 Lõi lọc diệt khuẩn Filter KA350S: số lượng: -1, đơn giá: 509,259 => Đảm bảo triệt tiêu số lượng, đơn giá, thành tiền | J9: Lõi lọc diệt khuẩn Filter KA350S: số lượng: -1, đơn giá: 509,259, thành tiền: -509,259 | L9: Kế toán | M9: 46306 | N9: =IF(COUNTA(H9:M9)=0,"Chưa phản hồi",IF(AND(H9<>"",I9<>"",J9<>"",K9<>""),"Đủ trường phản hồi","Cần bổ sung")) -> Cần bổ sung
A10: DC03 | B10: 1C25TUV/00003113 | C10: 45812 | D10: 1C25TUV/00013032 | E10: 45926 | F10: Vợt bắt muỗi tự động 2 trong 1 thu hút các loại côn trùng KM002. Hóa đơn gốc SL +1; điều chỉnh vẫn SL +1, đơn giá âm. Tổng tiền đã về 0, số lượng hai phía chưa triệt tiêu. | G10: Nghiệp vụ thực tế là giảm giá hay giảm/trả toàn bộ số lượng hàng? Chốt mục tiêu xử lý số lượng và giá trị, căn cứ và hướng xử lý điều chỉnh cũ. Đơn giá âm chưa tự chứng minh nội dung sai. | H10: Kế toán xuất sai HD 13032 | I10: Hóa đơn điều chỉnh cho HD 3113: giảm toàn bộ Vợt bắt muỗi tự động 2 trong 1 thu hút các loại côn trùng KM002: số lượng: -1, đơn giá: 163,889 Hóa đơn điều chỉnh cho HD 13038: Vợt bắt muỗi tự động 2 trong 1 thu hút các loại côn trùng KM002: số lượng: -1, đơn giá: 163,889 => Đảm bảo triệt tiêu số lượng, đơn giá, thành tiền | J10: Vợt bắt muỗi tự động 2 trong 1 thu hút các loại côn trùng KM002: số lượng: -1, đơn giá: 163,889 | L10: Kế toán | M10: 46306 | N10: =IF(COUNTA(H10:M10)=0,"Chưa phản hồi",IF(AND(H10<>"",I10<>"",J10<>"",K10<>""),"Đủ trường phản hồi","Cần bổ sung")) -> Cần bổ sung
A11: DC04 | B11: 1C25TUV/00004081 | C11: 45816 | D11: 1C25TUV/00013033 | E11: 45926 | F11: Vợt bắt muỗi tự động 2 trong 1 thu hút các loại côn trùng KM002. Hóa đơn gốc SL +1; điều chỉnh vẫn SL +1, đơn giá âm. Tổng tiền đã về 0, số lượng hai phía chưa triệt tiêu. | G11: Nghiệp vụ thực tế là giảm giá hay giảm/trả toàn bộ số lượng hàng? Chốt mục tiêu xử lý số lượng và giá trị, căn cứ và hướng xử lý điều chỉnh cũ. Đơn giá âm chưa tự chứng minh nội dung sai. | H11: Kế toán xuất sai HD 13033 | I11: Hóa đơn điều chỉnh cho HD 3113: giảm toàn bộ Vợt bắt muỗi tự động 2 trong 1 thu hút các loại côn trùng KM002: số lượng: -1, đơn giá: 165,741 Hóa đơn điều chỉnh cho HD 13038: Vợt bắt muỗi tự động 2 trong 1 thu hút các loại côn trùng KM002: số lượng: -1, đơn giá: 165,741 => Đảm bảo triệt tiêu số lượng, đơn giá, thành tiền | J11: Vợt bắt muỗi tự động 2 trong 1 thu hút các loại côn trùng KM002: số lượng: -1, đơn giá: 165,741 | L11: Kế toán | M11: 46306 | N11: =IF(COUNTA(H11:M11)=0,"Chưa phản hồi",IF(AND(H11<>"",I11<>"",J11<>"",K11<>""),"Đủ trường phản hồi","Cần bổ sung")) -> Cần bổ sung
A12: DC05 | B12: 1C25TUV/00005555 | C12: 45822 | D12: 1C25TUV/00013034 | E12: 45926 | F12: Vợt bắt muỗi tự động 2 trong 1 thu hút các loại côn trùng KM002. Hóa đơn gốc SL +1; điều chỉnh vẫn SL +1, đơn giá âm. Tổng tiền đã về 0, số lượng hai phía chưa triệt tiêu. | G12: Nghiệp vụ thực tế là giảm giá hay giảm/trả toàn bộ số lượng hàng? Chốt mục tiêu xử lý số lượng và giá trị, căn cứ và hướng xử lý điều chỉnh cũ. Đơn giá âm chưa tự chứng minh nội dung sai. | H12: Kế toán xuất sai HD 13034 | I12: Hóa đơn điều chỉnh cho HD 3113: giảm toàn bộ Vợt bắt muỗi tự động 2 trong 1 thu hút các loại côn trùng KM002: số lượng: -1, đơn giá: 165,740 Hóa đơn điều chỉnh cho HD 13038: Vợt bắt muỗi tự động 2 trong 1 thu hút các loại côn trùng KM002: số lượng: -1, đơn giá: 165,740 => Đảm bảo triệt tiêu số lượng, đơn giá, thành tiền | J12: Vợt bắt muỗi tự động 2 trong 1 thu hút các loại côn trùng KM002: số lượng: -1, đơn giá: 165,740 | L12: Kế toán | M12: 46306 | N12: =IF(COUNTA(H12:M12)=0,"Chưa phản hồi",IF(AND(H12<>"",I12<>"",J12<>"",K12<>""),"Đủ trường phản hồi","Cần bổ sung")) -> Cần bổ sung
A13: DC06 | B13: 1C25TUV/00005918 | C13: 45824 | D13: 1C25TUV/00013035 | E13: 45926 | F13: Vợt bắt muỗi tự động 2 trong 1 thu hút các loại côn trùng KM002. Hóa đơn gốc SL +1; điều chỉnh vẫn SL +1, đơn giá âm. Tổng tiền đã về 0, số lượng hai phía chưa triệt tiêu. | G13: Nghiệp vụ thực tế là giảm giá hay giảm/trả toàn bộ số lượng hàng? Chốt mục tiêu xử lý số lượng và giá trị, căn cứ và hướng xử lý điều chỉnh cũ. Đơn giá âm chưa tự chứng minh nội dung sai. | H13: Kế toán xuất sai HD 13035 | I13: Hóa đơn điều chỉnh cho HD 3113: giảm toàn bộ Vợt bắt muỗi tự động 2 trong 1 thu hút các loại côn trùng KM002: số lượng: -1, đơn giá: 165,741 Hóa đơn điều chỉnh cho HD 13038: Vợt bắt muỗi tự động 2 trong 1 thu hút các loại côn trùng KM002: số lượng: -1, đơn giá: 165,741 => Đảm bảo triệt tiêu số lượng, đơn giá, thành tiền | J13: Vợt bắt muỗi tự động 2 trong 1 thu hút các loại côn trùng KM002: số lượng: -1, đơn giá: 165,741 | L13: Kế toán | M13: 46306 | N13: =IF(COUNTA(H13:M13)=0,"Chưa phản hồi",IF(AND(H13<>"",I13<>"",J13<>"",K13<>""),"Đủ trường phản hồi","Cần bổ sung")) -> Cần bổ sung

Sheet Da co can cu
A2: Các hồ sơ đã có căn cứ hoặc quyết định
A3: Cập nhật | B3: 46306
A4: Giữ riêng để tham khảo khi xử lý tiếp; không yêu cầu kế toán xác nhận lại cùng thông tin.
A7: Mã hồ sơ | B7: Hóa đơn gốc | C7: Ngày gốc | D7: HĐ điều chỉnh liên quan | E7: Ngày điều chỉnh | F7: Nội dung đã làm rõ | G7: Việc chuẩn bị tiếp | H7: Hướng xử lý (KT điền)
A8: CC01 | B8: 1C24TUV/00000003 | C8: 45301 | D8: 1C25TUV/00000508 | E8: 45773 | F8: Phương án đảo khoản giảm 00000508 và giảm đầy đủ chi tiết gốc đã được người dùng chốt từ 09/10/2026. XML đã có; phần dòng khác tổng đã được ghi nhận. | G8: Tiếp tục chuẩn bị/cập nhật dữ liệu theo phương án đã chốt. Không yêu cầu chốt lại cùng phương án. | H8: Giữ nguyên, không xử lý điều chỉnh hóa đơn này
A9: CC02 | B9: 1C24TUV/00000498 | C9: 45565 | D9: 1C25TUV/00002140 | E9: 45807 | F9: XML 00002140 có thuế suất tổng hợp 8%. Tiền hàng 17.830.586, thuế 1.426.447, thanh toán 19.257.033. Không có danh sách dòng hàng. | G9: Dùng bằng chứng XML để chuẩn bị dữ liệu tiếp. Không yêu cầu tìm lại thuế suất chỉ vì bảng chi tiết không thể hiện. | H9: Giữ nguyên, không xử lý điều chỉnh hóa đơn này
A10: CC03 | B10: 1C24TUV/00000574 | C10: 45611 | D10: 1C25TUV/00002189 | E10: 45807 | F10: Người dùng đã chốt tạm tính thanh toán gốc bằng 0. Ô bảng tổng vẫn trống. Quy ước chỉ áp dụng cho hóa đơn này. | G10: Tiếp tục chuẩn bị dữ liệu theo quy ước riêng đã có. Không tự đổi ô nguồn hoặc mở rộng quy ước. | H10: Giữ nguyên, không xử lý điều chỉnh hóa đơn này
A11: CC04 | B11: 1C25TUV/00001348 | C11: 45804 | D11: 1C25TUV/00006108 | E11: 45825 | F11: XML điều chỉnh thông tin người mua; ba tổng tiền đều 0. Bảng kê để trống thanh toán. Nội dung thông tin người mua nằm trong ghi chú tham chiếu XML. | G11: Giữ nội dung điều chỉnh thông tin và phân biệt 0 trong XML với ô trống bảng kê khi chuẩn bị dữ liệu tiếp. | H11: Giữ nguyên, không xử lý điều chỉnh hóa đơn này
A12: CC05 | B12: 1C25TUV/00002377 | C12: 45807 | D12: 1C25TUV/00004203 | E12: 45817 | F12: XML điều chỉnh thông tin người mua; ba tổng tiền đều 0. Bảng kê để trống thanh toán. Nội dung thông tin người mua nằm trong ghi chú tham chiếu XML. | G12: Giữ nội dung điều chỉnh thông tin và phân biệt 0 trong XML với ô trống bảng kê khi chuẩn bị dữ liệu tiếp. | H12: Giữ nguyên, không xử lý điều chỉnh hóa đơn này
A13: CC06 | B13: 1C25TUV/00002378 | C13: 45807 | D13: 1C25TUV/00004204 | E13: 45817 | F13: XML điều chỉnh thông tin người mua; ba tổng tiền đều 0. Bảng kê để trống thanh toán. Nội dung thông tin người mua nằm trong ghi chú tham chiếu XML. | G13: Giữ nội dung điều chỉnh thông tin và phân biệt 0 trong XML với ô trống bảng kê khi chuẩn bị dữ liệu tiếp. | H13: Giữ nguyên, không xử lý điều chỉnh hóa đơn này
A14: CC07 | B14: 1C25TUV/00009072 | C14: 45836 | D14: 1C25TUV/00009186 | E14: 45837 | F14: XML điều chỉnh tên hàng có 2 dòng TChat=4; ba tổng tiền đều 0. Bảng kê để trống thanh toán. Nội dung đổi tên hàng đã có trong XML. | G14: Giữ nội dung điều chỉnh thông tin và phân biệt 0 trong XML với ô trống bảng kê khi chuẩn bị dữ liệu tiếp. | H14: Xuất điều chỉnh số lượng hàng hóa của hóa đơn 9072, còn hóa đơn 9186 thì kệ.

Sheet Hoa don lien quan
A2: Hóa đơn liên quan và căn cứ đối chiếu
A3: Cập nhật | B3: 46306
A4: Đơn vị tiền: đồng. Ô trống được giữ trống; số 0 là giá trị có trong nguồn.
A5: Nguồn: bảng kê xuất lại 09/10/2026, XML đã nhận, hai workbook hiện tại và quyết định đã ghi nhận.
A7: Mã hồ sơ | B7: Phạm vi công việc | C7: Vai trò | D7: Ký hiệu | E7: Số hóa đơn | F7: Ngày hóa đơn | G7: Tiền hàng bảng kê (đ) | H7: Thuế bảng kê (đ) | I7: Thanh toán bảng kê (đ) | J7: Tiền hàng XML (đ) | K7: Thuế XML (đ) | L7: Thanh toán XML (đ) | M7: Nội dung dòng/ghi chú cần đối chiếu | N7: Nguồn bảng kê | O7: File XML | P7: Ghi chú độ phủ nguồn
A8: LT01 | B8: Cần kế toán phản hồi | C8: Hóa đơn gốc | D8: 1C25TUV | E8: 00000159 | F8: 45716 | G8: 412037 | H8: 32963 | I8: 445000 | N8: Bang_ke_hoa_don_da_su_dung_1791532908545_1.xlsx, dòng 164 | P8: Chưa có XML trong phần nguồn đã lưu hiện tại.
A9: LT01 | B9: Cần kế toán phản hồi | C9: Điều chỉnh liên quan | D9: 1C25TUV | E9: 00000649 | F9: 45782 | G9: -381481 | H9: -30518 | I9: 411999 | J9: -381481 | K9: -30518 | L9: 411999 | M9: Điều chỉnh giảm giá trị hoá đơn số 00000159 Điều chỉnh giảm giá trị hoá đơn số 00000159 (TChat=1, SL=0, đơn giá=0, thành tiền=0) Thuế suất tổng hợp: 8% | N9: Bang_ke_hoa_don_da_su_dung_1791532908545_1.xlsx, dòng 654 | O9: 1C25TUV_00000649.xml | P9: Có XML trong bộ nguồn hiện tại.
A10: LT02 | B10: Cần kế toán phản hồi | C10: Hóa đơn gốc | D10: 1C25TUV | E10: 00000056 | F10: 45684 | G10: 2264222 | H10: 181138 | I10: 2445360 | N10: Bang_ke_hoa_don_da_su_dung_1791532908545_1.xlsx, dòng 61 | P10: Chưa có XML trong phần nguồn đã lưu hiện tại.
A11: LT02 | B11: Cần kế toán phản hồi | C11: Điều chỉnh liên quan | D11: 1C25TUV | E11: 00000561 | F11: 45781 | G11: 196889 | H11: 151751 | I11: 212640 | J11: 196889 | K11: 151751 | L11: 212640 | M11: Điều chỉnh tăng giá trị hóa đơn số 00000056 Điều chỉnh tăng giá trị hóa đơn số 00000056 (TChat=1, SL=0, đơn giá=0, thành tiền=0) Thuế suất tổng hợp: 8% | N11: Bang_ke_hoa_don_da_su_dung_1791532908545_1.xlsx, dòng 566 | O11: 1C25TUV_00000561.xml | P11: Có XML trong bộ nguồn hiện tại.
A12: LT03 | B12: Cần kế toán phản hồi | C12: Hóa đơn gốc | D12: 1C24TUV | E12: 00000283 | F12: 45457 | G12: 90142915 | H12: 7211433 | I12: 97354348 | N12: Bang_ke_hoa_don_da_su_dung_1791532882546.xlsx, dòng 288 | P12: Chưa có XML trong phần nguồn đã lưu hiện tại.
A13: LT03 | B13: Cần kế toán phản hồi | C13: Điều chỉnh liên quan | D13: 1C25TUV | E13: 00001819 | F13: 45806 | G13: 7599678 | H13: 609974 | I13: 8207652 | J13: 7599678 | K13: 609974 | L13: 8207652 | M13: Điều chỉnh tăng thành tiền hoá đơn số 00000283 Điều chỉnh tăng thành tiền hoá đơn số 00000283 (TChat=1, SL=0, đơn giá=0, thành tiền=0) Thuế suất tổng hợp: 8% | N13: Bang_ke_hoa_don_da_su_dung_1791532908545_1.xlsx, dòng 1824 | O13: 1C25TUV_00001819.xml | P13: Có XML trong bộ nguồn hiện tại.
A14: LT04 | B14: Cần kế toán phản hồi | C14: Hóa đơn gốc | D14: 1C24TUV | E14: 00000093 | F14: 45352 | G14: 20222499 | H14: 1617800 | I14: 21840299 | N14: Bang_ke_hoa_don_da_su_dung_1791532882546.xlsx, dòng 98 | P14: Chưa có XML trong phần nguồn đã lưu hiện tại.
A15: LT04 | B15: Cần kế toán phản hồi | C15: Điều chỉnh liên quan | D15: 1C25TUV | E15: 00001167 | F15: 45803 | G15: 621945 | H15: 49756 | I15: 670701 | J15: 621945 | K15: 49756 | L15: 670701 | M15: Điều chỉnh tăng thành tiền hoá đơn số 00000093 Điều chỉnh tăng thành tiền hoá đơn số 00000093 (TChat=1, SL=0, đơn giá=0, thành tiền=0) Thuế suất tổng hợp: 8% | N15: Bang_ke_hoa_don_da_su_dung_1791532908545_1.xlsx, dòng 1172 | O15: 1C25TUV_00001167.xml | P15: Có XML trong bộ nguồn hiện tại.
A16: LT05 | B16: Cần kế toán phản hồi | C16: Hóa đơn gốc | D16: 1C24TUV | E16: 00000535 | F16: 45587 | G16: 180276018 | H16: 14422081 | I16: 194698099 | N16: Bang_ke_hoa_don_da_su_dung_1791532882546.xlsx, dòng 540 | P16: Chưa có XML trong phần nguồn đã lưu hiện tại.
A17: LT05 | B17: Cần kế toán phản hồi | C17: Điều chỉnh liên quan | D17: 1C25TUV | E17: 00002145 | F17: 45807 | G17: 39194352 | H17: 3135548 | I17: 42329000 | J17: 39194352 | K17: 3135548 | L17: 42329000 | M17: Điều chỉnh tăng giá trị hóa đơn số 00000535 Điều chỉnh tăng giá trị hóa đơn số 00000535 (TChat=1, SL=0, đơn giá=0, thành tiền=0) Thuế suất tổng hợp: 8% | N17: Bang_ke_hoa_don_da_su_dung_1791532908545_1.xlsx, dòng 2150 | O17: 1C25TUV_00002145.xml | P17: Có XML trong bộ nguồn hiện tại.
A18: LT06 | B18: Cần kế toán phản hồi | C18: Hóa đơn gốc | D18: 1C24TUV | E18: 00000228 | F18: 45425 | G18: 10131221 | H18: 810498 | I18: 10941719 | N18: Bang_ke_hoa_don_da_su_dung_1791532882546.xlsx, dòng 233 | P18: Chưa có XML trong phần nguồn đã lưu hiện tại.
A19: LT06 | B19: Cần kế toán phản hồi | C19: Điều chỉnh liên quan | D19: 1C25TUV | E19: 00002619 | F19: 45808 | G19: -589554 | H19: -47164 | I19: -636719 | J19: -589554 | K19: -47164 | L19: -636719 | M19: Điều chỉnh giảm giá trị hóa đơn số 00000228 Điều chỉnh giảm giá trị hóa đơn số 00000228 (TChat=1, SL=0, đơn giá=0, thành tiền=0) Thuế suất tổng hợp: 8% | N19: Bang_ke_hoa_don_da_su_dung_1791532908545_1.xlsx, dòng 2624 | O19: 1C25TUV_00002619.xml | P19: Có XML trong bộ nguồn hiện tại.
A20: LT06 | B20: Cần kế toán phản hồi | C20: Điều chỉnh liên quan | D20: 1C25TUV | E20: 00002646 | F20: 45808 | G20: 1718981 | H20: 137518 | I20: 1856499 | J20: 1718981 | K20: 137518 | L20: 1856499 | M20: Điều chỉnh tăng giá trị hoá đơn số 00000228 Điều chỉnh tăng giá trị hoá đơn số 00000228 (TChat=1, SL=0, đơn giá=0, thành tiền=0) Thuế suất tổng hợp: 8% | N20: Bang_ke_hoa_don_da_su_dung_1791532908545_1.xlsx, dòng 2651 | O20: 1C25TUV_00002646.xml | P20: Có XML trong bộ nguồn hiện tại.
A21: LT07 | B21: Cần kế toán phản hồi | C21: Hóa đơn gốc | D21: 1C24TUV | E21: 00000285 | F21: 45458 | G21: 87458193 | H21: 6996655 | I21: 94454848 | N21: Bang_ke_hoa_don_da_su_dung_1791532882546.xlsx, dòng 290 | P21: Chưa có XML trong phần nguồn đã lưu hiện tại.
A22: LT07 | B22: Cần kế toán phản hồi | C22: Điều chỉnh liên quan | D22: 1C25TUV | E22: 00001821 | F22: 45806 | G22: 5701066 | H22: 456085 | I22: 6157152 | J22: 5701066 | K22: 456085 | L22: 6157152 | M22: Điều chỉnh tăng thành tiền hoá đơn số 00000285 Điều chỉnh tăng thành tiền hoá đơn số 00000285 (TChat=1, SL=0, đơn giá=0, thành tiền=0) Thuế suất tổng hợp: 8% | N22: Bang_ke_hoa_don_da_su_dung_1791532908545_1.xlsx, dòng 1826 | O22: 1C25TUV_00001821.xml | P22: Có XML trong bộ nguồn hiện tại.
A23: LT08 | B23: Cần kế toán phản hồi | C23: Hóa đơn gốc | D23: 1C25TUV | E23: 00000102 | F23: 45707 | G23: 69918243 | H23: 5593459 | I23: 75511702 | N23: Bang_ke_hoa_don_da_su_dung_1791532908545_1.xlsx, dòng 107 | P23: Chưa có XML trong phần nguồn đã lưu hiện tại.
A24: LT08 | B24: Cần kế toán phản hồi | C24: Điều chỉnh liên quan | D24: 1C25TUV | E24: 00000626 | F24: 45781 | G24: 4347265 | H24: 347781 | I24: 4695045 | J24: 4347265 | K24: 347781 | L24: 4695045 | M24: Điều chỉnh tăng giá trị hoá đơn số 00000102 Điều chỉnh tăng giá trị hoá đơn số 00000102 (TChat=1, SL=0, đơn giá=0, thành tiền=0) Thuế suất tổng hợp: 8% | N24: Bang_ke_hoa_don_da_su_dung_1791532908545_1.xlsx, dòng 631 | O24: 1C25TUV_00000626.xml | P24: Có XML trong bộ nguồn hiện tại.
A25: SL01 | B25: Cần kế toán phản hồi | C25: Hóa đơn gốc | D25: 1C24TUV | E25: 00000555 | F25: 45596 | G25: 6219445 | H25: 497556 | I25: 6717001 | M25: Màng Lọc HEPA H13 Diệt Khuẩn Cho Máy Lọc Không Khí UVGREEN KA350 FT ( BS HĐ 547): SL=trống, đơn giá=trống, tiền hàng=46296, thuế=3705, thanh toán=50001 | N25: Bang_ke_hoa_don_da_su_dung_1791532882546.xlsx, dòng 560 | P25: Chưa có XML trong phần nguồn đã lưu hiện tại.
A26: SL01 | B26: Cần kế toán phản hồi | C26: Điều chỉnh liên quan | D26: 1C25TUV | E26: 00002632 | F26: 45808 | G26: -1888889 | H26: -151111 | I26: -2040000 | J26: -1888889 | K26: -151111 | L26: -2040000 | M26: Điều chỉnh giảm giá trị hoá đơn số 00000555 Điều chỉnh giảm giá trị hoá đơn số 00000555 (TChat=1, SL=0, đơn giá=0, thành tiền=0) Thuế suất tổng hợp: 8% | N26: Bang_ke_hoa_don_da_su_dung_1791532908545_1.xlsx, dòng 2637 | O26: 1C25TUV_00002632.xml | P26: Có XML trong bộ nguồn hiện tại.
A27: SL02 | B27: Cần kế toán phản hồi | C27: Hóa đơn gốc | D27: 1C25TUV | E27: 00000113 | F27: 45707 | G27: 46178880 | H27: 3694310 | I27: 49873190 | M27: Màng Lọc (Lõi Lọc) HEPA H13 Diệt Khuẩn Cho Máy Lọc Không Khí UVGREEN KA600 FT: SL=trống, đơn giá=trống, tiền hàng=trống, thuế=trống, thanh toán=trống | N27: Bang_ke_hoa_don_da_su_dung_1791532908545_1.xlsx, dòng 118 | P27: Chưa có XML trong phần nguồn đã lưu hiện tại.
A28: SL02 | B28: Cần kế toán phản hồi | C28: Điều chỉnh liên quan | D28: 1C25TUV | E28: 00000635 | F28: 45782 | G28: 446836 | H28: 35747 | I28: 482583 | J28: 446836 | K28: 35747 | L28: 482583 | M28: Điều chỉnh tăng giá trị hoá đơn số 00000113 Điều chỉnh tăng giá trị hoá đơn số 00000113 (TChat=1, SL=0, đơn giá=0, thành tiền=0) Thuế suất tổng hợp: 8% | N28: Bang_ke_hoa_don_da_su_dung_1791532908545_1.xlsx, dòng 640 | O28: 1C25TUV_00000635.xml | P28: Có XML trong bộ nguồn hiện tại.
A29: SL03 | B29: Cần kế toán phản hồi | C29: Hóa đơn gốc | D29: 1C24TUV | E29: 00000774 | F29: 45657 | G29: 4398148 | H29: 351852 | I29: 4750000 | M29: ( Hàng biếu, tặng không thu tiền): SL/đơn giá/thành tiền lưu = 0 ở bảng kiểm. | N29: Bang_ke_hoa_don_da_su_dung_1791532882546.xlsx, dòng 779 | P29: Chưa có XML trong phần nguồn đã lưu hiện tại.
A30: SL04 | B30: Cần kế toán phản hồi | C30: Hóa đơn gốc | D30: 1C24TUV | E30: 00000783 | F30: 45657 | G30: 18240741 | H30: 1459259 | I30: 19700000 | M30: ( Hàng tặng không thu tiền): SL/đơn giá/thành tiền lưu = 0 ở bảng kiểm. | N30: Bang_ke_hoa_don_da_su_dung_1791532882546.xlsx, dòng 788 | P30: Chưa có XML trong phần nguồn đã lưu hiện tại.
A31: SL05 | B31: Cần kế toán phản hồi | C31: Hóa đơn gốc | D31: 1C24TUV | E31: 00000784 | F31: 45657 | G31: 4629630 | H31: 370370 | I31: 5000000 | M31: ( Hàng tặng không thu tiền): SL/đơn giá/thành tiền lưu = 0 ở bảng kiểm. | N31: Bang_ke_hoa_don_da_su_dung_1791532882546.xlsx, dòng 789 | P31: Chưa có XML trong phần nguồn đã lưu hiện tại.
A32: SL06 | B32: Cần kế toán phản hồi | C32: Hóa đơn gốc | D32: 1C24TUV | E32: 00000786 | F32: 45657 | G32: 25879630 | H32: 2070370 | I32: 27950000 | M32: ( hàng tặng không thu tiền): SL/đơn giá/thành tiền lưu = 0 ở bảng kiểm. | N32: Bang_ke_hoa_don_da_su_dung_1791532882546.xlsx, dòng 791 | P32: Chưa có XML trong phần nguồn đã lưu hiện tại.
A33: SL07 | B33: Cần kế toán phản hồi | C33: Hóa đơn gốc | D33: 1C25TUV | E33: 00002796 | F33: 45809 | G33: 443519 | H33: 35482 | I33: 479001 | M33: Vợt bắt muỗi tự động 2 trong 1 thu hút các loại côn trùng KM002: SL/đơn giá/thành tiền lưu = 0 ở bảng kiểm. | N33: Bang_ke_hoa_don_da_su_dung_1791532908545_1.xlsx, dòng 2801 | P33: Chưa có XML trong phần nguồn đã lưu hiện tại.
A34: SL08 | B34: Cần kế toán phản hồi | C34: Hóa đơn gốc | D34: 1C25TUV | E34: 00002797 | F34: 45809 | G34: 1213008 | H34: 97041 | I34: 1310049 | M34: Vợt bắt muỗi tự động 2 trong 1 thu hút các loại côn trùng KM003: SL/đơn giá/thành tiền lưu = 0 ở bảng kiểm. | N34: Bang_ke_hoa_don_da_su_dung_1791532908545_1.xlsx, dòng 2802 | P34: Chưa có XML trong phần nguồn đã lưu hiện tại.
A35: TT01 | B35: Cần kế toán phản hồi | C35: Hóa đơn gốc | D35: 1C25TUV | E35: 00000006 | F35: 45664 | G35: 0 | H35: 0 | N35: Bang_ke_hoa_don_da_su_dung_1791532908545_1.xlsx, dòng 11 | P35: Chưa có XML trong phần nguồn đã lưu hiện tại.
A36: TT01 | B36: Cần kế toán phản hồi | C36: Điều chỉnh liên quan | D36: 1C25TUV | E36: 00000655 | F36: 45782 | G36: 3478704 | H36: 278296 | I36: 3757000 | J36: 3478704 | K36: 278296 | L36: 3757000 | M36: Điều chỉnh tăng giá trị hóa đơn số 00000006 Điều chỉnh tăng giá trị hóa đơn số 00000006 (TChat=1, SL=0, đơn giá=0, thành tiền=0) Thuế suất tổng hợp: 8% | N36: Bang_ke_hoa_don_da_su_dung_1791532908545_1.xlsx, dòng 660 | O36: 1C25TUV_00000655.xml | P36: Có XML trong bộ nguồn hiện tại.
A37: TT02 | B37: Cần kế toán phản hồi | C37: Hóa đơn gốc | D37: 1C25TUV | E37: 00000016 | F37: 45671 | G37: 0 | H37: 0 | N37: Bang_ke_hoa_don_da_su_dung_1791532908545_1.xlsx, dòng 21 | P37: Chưa có XML trong phần nguồn đã lưu hiện tại.
A38: TT02 | B38: Cần kế toán phản hồi | C38: Điều chỉnh liên quan | D38: 1C25TUV | E38: 00000657 | F38: 45782 | G38: 5275000 | H38: 422000 | I38: 5697000 | J38: 5275000 | K38: 422000 | L38: 5697000 | M38: Điều chỉnh tăng giá trị hóa đơn số 00000016 Điều chỉnh tăng giá trị hóa đơn số 00000016 (TChat=1, SL=0, đơn giá=0, thành tiền=0) Thuế suất tổng hợp: 8% | N38: Bang_ke_hoa_don_da_su_dung_1791532908545_1.xlsx, dòng 662 | O38: 1C25TUV_00000657.xml | P38: Có XML trong bộ nguồn hiện tại.
A39: HH01 | B39: Cần kế toán phản hồi | C39: Hóa đơn gốc | D39: 1C25TUV | E39: 00003548 | F39: 45814 | G39: 962037 | H39: 76963 | I39: 1039000 | N39: Bang_ke_hoa_don_da_su_dung_1791532908545_1.xlsx, dòng 3553 | P39: Chưa có XML trong phần nguồn đã lưu hiện tại.
A40: HH01 | B40: Cần kế toán phản hồi | C40: Điều chỉnh liên quan | D40: 1C25TUV | E40: 00013072 | F40: 45930 | G40: -962037 | H40: -76963 | I40: -1039000 | J40: -962037 | K40: -76963 | L40: -1039000 | M40: Điều chỉnh giảm do đổi trả hàng hóa theo hóa đơn số :00003548 ngày 06 tháng 06 năm 2025 Lõi lọc diệt khuẩn - Filter - KA150S (TChat=1, SL=-1, đơn giá=962037, thành tiền=-962037) Thuế suất tổng hợp: 8% | N40: Bang_ke_hoa_don_da_su_dung_1791532908545_6.xlsx, dòng 3862 | O40: 1C25TUV_00013072.xml | P40: Có XML trong bộ nguồn hiện tại.
A41: HH02 | B41: Cần kế toán phản hồi | C41: Hóa đơn gốc | D41: 1C25TUV | E41: 00004026 | F41: 45816 | G41: 499074 | H41: 39926 | I41: 539000 | N41: Bang_ke_hoa_don_da_su_dung_1791532908545_1.xlsx, dòng 4031 | P41: Chưa có XML trong phần nguồn đã lưu hiện tại.
A42: HH02 | B42: Cần kế toán phản hồi | C42: Điều chỉnh liên quan | D42: 1C25TUV | E42: 00013079 | F42: 45930 | G42: -499074 | H42: -39926 | I42: -539000 | J42: -499074 | K42: -39926 | L42: -539000 | M42: Điều chỉnh giảm do đổi trả hàng hóa theo hóa đơn số :00004026 ngày 08 tháng 06 năm 2025 Máy phun sương tạo độ ẩm không khí diệt khuẩn bằng tia UVC với màn hình LCD - KH100 (TChat=1, SL=-1, đơn giá=499074, thành tiền=-499074) Thuế suất tổng hợp: 8% | N42: Bang_ke_hoa_don_da_su_dung_1791532908545_6.xlsx, dòng 3869 | O42: 1C25TUV_00013079.xml | P42: Có XML trong bộ nguồn hiện tại.
...
