Workbook

Sheet HD cty 2024
A1: Ký hiệu | B1: Số hóa đơn | C1: Ngày hóa đơn | D1: MST | E1: Tên công ty | F1: Địa chỉ | G1: Tiền hàng | H1: Tiền thuế | I1: Thanh toán | J1: Trạng thái hóa đơn | K1: Số đơn hàng | L1: Tên Sàn | M1: BHH | N1: Note | O1: Tiền hàng | P1: Tiền thuế | Q1: Hóa đơn điều chỉnh liên quan | R1: Tiền hàng | S1: Tiền thuế | T1: Thành tiền sau điều chỉnh | U1: Thuế sau điều chỉnh | V1: Lệch tiền hàng so với Amis | W1: Lệch tiền thuế so với Amis | X1: Hướng xử lý (Note 25,10,2026)
A2: 1C24TUV | B2: 634 | C2: 03/12/2024 | D2: 4001091085 | E2: DOANH NGHIỆP TƯ NHÂN DU LỊCH AN PHÁT | F2: 301 Nguyễn Duy Hiệu, Phường Sơn Phong, Thành phố Hội An, Tỉnh Quảng Nam, Việt Nam | G2: 1517593 | H2: 121407 | I2: 1639000 | J2: Hóa đơn đã bị điều chỉnh | K2: 241129FVW621DF | L2: Shopee | M2: BHHS2024008034 | O2: 1702778 | P2: 136222 | Q2: 00002591 | R2: 185185 | S2: 14815 | T2: =G2+R2 -> 1702778 | U2: =H2+S2 -> 136222 | V2: =O2-G2-R2 -> 0 | W2: =P2-H2-S2 -> 0
A3: 1C24TUV | B3: 642 | C3: 04/12/2024 | D3: 0312239812 | E3: CÔNG TY TNHH MỘT THÀNH VIÊN XĂNG DẦU SONG ĐĂNG | F3: D19/28 Hương Lộ 80, ấp 4, Xã Vĩnh Lộc B, Huyện Bình Chánh, Thành phố Hồ Chí Minh, Việt Nam | G3: 2480556 | H3: 198444 | I3: 2679000 | J3: Hóa đơn đã bị điều chỉnh | K3: 241130JYVEQAPY | L3: Shopee | M3: BHHS2024008128 | O3: 2573148 | P3: 205852 | Q3: 00002592 | R3: 92592 | S3: 7407 | T3: =G3+R3 -> 2573148 | U3: =H3+S3 -> 205851 | V3: =O3-G3-R3 -> 0 | W3: =P3-H3-S3 -> 1
A4: 1C24TUV | B4: 650 | C4: 05/12/2024 | D4: 0318588954 | E4: CÔNG TY TNHH CHÚ CÁ | F4: 33 Tân Trụ, Phường 15, Quận Tân Bình, Thành phố Hồ Chí Minh, Việt Nam | G4: 25555556 | H4: 2044444 | I4: 27600000 | J4: Hóa đơn mới | K4: HD007378.01 | L4: Ngoài sàn | M4: BHHN2024000017 | O4: 25555556 | P4: 2044444 | V4: =O4-G4-R4 -> 0 | W4: =P4-H4-S4 -> 0
A5: 1C24TUV | B5: 651 | C5: 09/12/2024 | D5: 0202232740 | E5: CÔNG TY TNHH THƯƠNG MẠI DỊCH VỤ VÀ VẬN CHUYỂN AECP | F5: Số 2C/280 Trung Lực, Phường Đằng Lâm, Quận Hải An, Thành phố Hải Phòng, Việt Nam | G5: 2573148 | H5: 205852 | I5: 2779000 | J5: Hóa đơn mới | K5: 241130KSXRS8QW | L5: Shopee | M5: BHHS2024008146 | O5: 2573148 | P5: 205852 | V5: =O5-G5-R5 -> 0 | W5: =P5-H5-S5 -> 0
A6: 1C24TUV | B6: 659 | C6: 11/12/2024 | D6: 0109724748 | E6: CÔNG TY CỔ PHẦN VGENTECH | F6: Xóm 8, thôn Việt Yên, Xã Ngũ Hiệp, Huyện Thanh Trì, Thành phố Hà Nội, Việt Nam | G6: 2397221 | H6: 191778 | I6: 2588999 | J6: Hóa đơn đã bị điều chỉnh | K6: 579703438136150806 | L6: Tiktok | M6: BHHT2024024139 | O6: 2813888 | P6: 225111 | Q6: 00002639 | R6: 416667 | S6: 33333 | T6: =G6+R6 -> 2813888 | U6: =H6+S6 -> 225111 | V6: =O6-G6-R6 -> 0 | W6: =P6-H6-S6 -> 0
A7: 1C24TUV | B7: 660 | C7: 13/12/2024 | D7: 0315729798 | E7: CÔNG TY TNHH THỰC PHẨM TOÀN CẦU HUY HOÀNG | F7: 85 Hoàng Sa, Phường Đa Kao, Quận 1, Thành phố Hồ Chí Minh, Việt Nam | G7: 2276870 | H7: 182150 | I7: 2459020 | J7: Hóa đơn đã bị điều chỉnh | K7: 241212KM47RTQK | L7: Shopee | M7: BHHS2024008520 | O7: 2573148 | P7: 205852 | Q7: 00002219 | R7: 296278 | S7: 23702 | T7: =G7+R7 -> 2573148 | U7: =H7+S7 -> 205852 | V7: =O7-G7-R7 -> 0 | W7: =P7-H7-S7 -> 0
A8: 1C24TUV | B8: 661 | C8: 16/12/2024 | D8: 0303427866 | E8: CÔNG TY TNHH TIẾP VẬN VẬN TẢI QUỐC TẾ VÕ LƯƠNG | F8: 174/13 Điện Biên Phủ, Phường 17, Quận Bình Thạnh, Thành phố Hồ Chí Minh, Việt Nam | G8: 2315833 | H8: 185267 | I8: 2501100 | J8: Hóa đơn đã bị điều chỉnh | K8: 241212KHD7Y219 | L8: Shopee | M8: BHHS2024008508 | O8: 2573148 | P8: 205852 | Q8: 00002220 | R8: 257315 | S8: 20585 | T8: =G8+R8 -> 2573148 | U8: =H8+S8 -> 205852 | V8: =O8-G8-R8 -> 0 | W8: =P8-H8-S8 -> 0
A9: 1C24TUV | B9: 668 | C9: 17/12/2024 | D9: 1701239486 | E9: CÔNG TY CỔ PHẦN SÀI GÒN DƯƠNG ĐÔNG | F9: Đường Cách Mạng Tháng Tám, khu phố 6, Phường Dương Đông, Thành phố Phú Quốc, Tỉnh Kiên Giang, Việt Nam | G9: 846593 | H9: 67727 | I9: 914320 | J9: Hóa đơn đã bị điều chỉnh | K9: 241212M6VCV4RW | L9: Shopee | M9: BHHS2024008591 | O9: 962037 | P9: 76963 | Q9: 00002595 | R9: 115444 | S9: 9236 | T9: =G9+R9 -> 962037 | U9: =H9+S9 -> 76963 | V9: =O9-G9-R9 -> 0 | W9: =P9-H9-S9 -> 0
A10: 1C24TUV | B10: 696 | C10: 21/12/2024 | D10: 4000394369 | E10: CÔNG TY TRÁCH NHIỆM HỮU HẠN YEOU LIH SILICA SAND VIỆT NAM | F10: Thôn Mỹ Bình, Xã Tam Hiệp, Huyện Núi Thành, Tỉnh Quảng Nam, Việt Nam | G10: 1149167 | H10: 91933 | I10: 1241100 | J10: Hóa đơn mới | K10: 241127B8V2GTBF | L10: Shopee | M10: BHHS2024007985 | O10: 1276852 | P10: 102148 | V10: =O10-G10-R10 -> 127685 | W10: =P10-H10-S10 -> 10215
A11: 1C24TUV | B11: 698 | C11: 21/12/2024 | D11: 0314069690 | E11: CÔNG TY TNHH LANDO | F11: 416E Nguyễn Thị Minh Khai, Phường 05, Quận 3, Thành phố Hồ Chí Minh, Việt Nam | G11: 865574 | H11: 69246 | I11: 934820 | J11: Hóa đơn đã bị điều chỉnh | K11: 241212MQUR80DS | L11: Shopee | M11: BHHS2024008614 | O11: 962037 | P11: 76963 | Q11: 00002596 | R11: 96463 | S11: 7717 | T11: =G11+R11 -> 962037 | U11: =H11+S11 -> 76963 | V11: =O11-G11-R11 -> 0 | W11: =P11-H11-S11 -> 0
A12: 1C24TUV | B12: 718 | C12: 25/12/2024 | D12: 0402181645 | E12: CÔNG TY TNHH MTV ECOMDY | F12: 55 Lê Quang Hòa, Phường Hoà Xuân, Quận Cẩm Lệ, Thành phố Đà Nẵng, Việt Nam | G12: 865833 | H12: 69267 | I12: 935100 | J12: Hóa đơn đã bị điều chỉnh | K12: 241222G3V1MPRP | L12: Shopee | M12: BHHS2024008901 | O12: 962037 | P12: 76963 | Q12: 00002597 | R12: 96204 | S12: 7696 | T12: =G12+R12 -> 962037 | U12: =H12+S12 -> 76963 | V12: =O12-G12-R12 -> 0 | W12: =P12-H12-S12 -> 0
A13: 1C24TUV | B13: 719 | C13: 25/12/2024 | D13: 0700836294 | E13: CÔNG TY TNHH HOURENSOU VIỆT NAM | F13: Số 39 Tân Khai, Phường Minh Khai, Thành phố Phủ Lý, Tỉnh Hà Nam, Việt Nam | G13: 6793611 | H13: 543489 | I13: 7337100 | J13: Hóa đơn đã bị điều chỉnh | K13: 579780912382053031 | L13: Tiktok | M13: BHHT2024022934 | O13: 7095370 | P13: 567630 | Q13: 00002275 | R13: 301759 | S13: 24141 | T13: =G13+R13 -> 7095370 | U13: =H13+S13 -> 567630 | V13: =O13-G13-R13 -> 0 | W13: =P13-H13-S13 -> 0
A14: 1C24TUV | B14: 563 | C14: 07/11/2024 | D14: 0318401003 | E14: CÔNG TY TNHH XUẤT NHẬP KHẨU GOLDEN SUCCESS | F14: 60/6 Yên Thế, Phường 2, Quận Tân Bình, Thành phố Hồ Chí Minh, Việt Nam | G14: 5008037 | H14: 400643 | I14: 5408680 | J14: Hóa đơn đã bị điều chỉnh | K14: 241029SAKRK9H4 | L14: Shopee | M14: BHHS2024007137 | O14: 5443519 | P14: 435481 | Q14: 00002171 | R14: 435482 | S14: 34839 | T14: =G14+R14 -> 5443519 | U14: =H14+S14 -> 435482 | V14: =O14-G14-R14 -> 0 | W14: =P14-H14-S14 -> -1
A15: 1C24TUV | B15: 564 | C15: 07/11/2024 | D15: 0100731483 | E15: VIỆN KHOA HỌC CÔNG NGHỆ VÀ KINH TẾ XÂY DỰNG HÀ NỘI | F15: 38 phố cát linh, Phường Cát Linh, Quận Đống đa, Thành phố Hà Nội, Việt Nam | G15: 3823148 | H15: 305852 | I15: 4129000 | J15: Hóa đơn đã bị điều chỉnh | K15: 241030VSSYK2H6 | L15: Shopee | M15: BHHS2024007171 | O15: 4054630 | P15: 324370 | Q15: 00002172 | R15: 231482 | S15: 18519 | T15: =G15+R15 -> 4054630 | U15: =H15+S15 -> 324371 | V15: =O15-G15-R15 -> 0 | W15: =P15-H15-S15 -> -1
A16: 1C24TUV | B16: 566 | C16: 12/11/2024 | D16: 0100731483 | E16: VIỆN KHOA HỌC CÔNG NGHỆ VÀ KINH TẾ XÂY DỰNG HÀ NỘI | F16: 38 phố cát linh, Phường Cát Linh, Quận Đống đa, Thành phố Hà Nội, Việt Nam | G16: 3482500 | H16: 278600 | I16: 3761100 | J16: Hóa đơn đã bị điều chỉnh | K16: 241106GHXRY2CA | L16: Shopee | M16: BHHS2024007332 | O16: 3869444 | P16: 309556 | Q16: 00002174 | R16: 386944 | S16: 30956 | T16: =G16+R16 -> 3869444 | U16: =H16+S16 -> 309556 | V16: =O16-G16-R16 -> 0 | W16: =P16-H16-S16 -> 0
A17: 1C24TUV | B17: 567 | C17: 12/11/2024 | D17: 3702483628 | E17: CÔNG TY TNHH KHÁCH SẠN NỮ HOÀNG ELIZABETH | F17: Số 17/41, Trần Văn ơn, Khu phố 6, Phường Phú Hòa, Thành phố Thủ Dầu Một, Tỉnh Bình Dương, Việt Nam | G17: 813889 | H17: 65111 | I17: 879000 | J17: Hóa đơn đã bị điều chỉnh | K17: 579621705911404561 | L17: Tiktok | M17: BHHT2024021302 | O17: 962037 | P17: 76963 | Q17: 00002635 | R17: 148148 | S17: 11852 | T17: =G17+R17 -> 962037 | U17: =H17+S17 -> 76963 | V17: =O17-G17-R17 -> 0 | W17: =P17-H17-S17 -> 0
A18: 1C24TUV | B18: 568 | C18: 13/11/2024 | D18: 6400397008 | E18: CÔNG TY TNHH MỘT THÀNH VIÊN XÂY DỰNG XUÂN TRƯỜNG ĐẮK NÔNG | F18: Tổ 1, Phường Nghĩa Trung, Thành phố Gia Nghĩa, Tỉnh Đắk Nông, Việt Nam | G18: 1726852 | H18: 138148 | I18: 1865000 | J18: Hóa đơn đã bị điều chỉnh | K18: 579622523415529731 | L18: Tiktok | M18: BHHT2024021233 | O18: 1884630 | P18: 150770 | Q18: 00002636 | R18: 157778 | S18: 12622 | T18: =G18+R18 -> 1884630 | U18: =H18+S18 -> 150770 | V18: =O18-G18-R18 -> 0 | W18: =P18-H18-S18 -> 0
A19: 1C24TUV | B19: 579 | C19: 18/11/2024 | D19: 0311950572 | E19: CÔNG TY CỔ PHẦN QUẢNG CÁO VÀ THƯƠNG MẠI GSOLUTION | F19: 90/12/1/16 Bông Sao, Phường 5, Quận 8, Thành phố Hồ Chí Minh, Việt Nam | G19: 1982500 | H19: 158600 | I19: 2141100 | J19: Hóa đơn đã bị điều chỉnh | K19: 2411135SNXVAA1 | L19: Shopee | M19: BHHS2024007662 | O19: 2387963 | P19: 191037 | Q19: 00002589 | R19: 405463 | S19: 32437 | T19: =G19+R19 -> 2387963 | U19: =H19+S19 -> 191037 | V19: =O19-G19-R19 -> 0 | W19: =P19-H19-S19 -> 0
A20: 1C24TUV | B20: 599 | C20: 25/11/2024 | D20: 6400448686 | E20: CÔNG TY TNHH XUẤT NHẬP KHẨU MACA HILLS | F20: Tổ dân phố 3, Phường Nghĩa Thành, Thành phố Gia Nghĩa, Tỉnh Đắk Nông, Việt Nam | G20: 1047019 | H20: 83762 | I20: 1130781 | J20: Hóa đơn đã bị điều chỉnh | K20: 579669737495824617 | L20: Tiktok | M20: BHHT2024019990 | O20: 1276852 | P20: 102148 | Q20: 00002196 | R20: 229833 | S20: 18387 | T20: =G20+R20 -> 1276852 | U20: =H20+S20 -> 102149 | V20: =O20-G20-R20 -> 0 | W20: =P20-H20-S20 -> -1
A21: 1C24TUV | B21: 603 | C21: 26/11/2024 | D21: 0317749976 | E21: CÔNG TY TNHH THƯƠNG MẠI DỊCH VỤ VẬT TƯ TRẦN LÂM | F21: 134/5/28 BIS Lạc Long Quân, Phường 3, Quận 11, Thành phố Hồ Chí Minh, Việt Nam | G21: 3446435 | H21: 275715 | I21: 3722150 | J21: Hóa đơn đã bị điều chỉnh | K21: 2411110BWBFW6F | L21: Shopee | M21: BHHS2024007540 | O21: 4054630 | P21: 324370 | Q21: 00002179 | R21: 608195 | S21: 48656 | T21: =G21+R21 -> 4054630 | U21: =H21+S21 -> 324371 | V21: =O21-G21-R21 -> 0 | W21: =P21-H21-S21 -> -1
A22: 1C24TUV | B22: 609 | C22: 27/11/2024 | D22: 0102641429 | E22: TỔNG CÔNG TY BẢO VIỆT NHÂN THỌ | F22: Tầng 37, Keangnam Ha Noi Landmark Tower, đường Phạm Hùng, Phường Mễ Trì, Quận Nam Từ Liêm, Thành phố Hà Nội, Việt Nam | G22: 2341667 | H22: 187333 | I22: 2529000 | J22: Hóa đơn đã bị điều chỉnh | K22: 579678018260928910 | L22: Tiktok | M22: BHHT2024019852 | O22: 2526852 | P22: 202148 | Q22: 00002638 | R22: 185185 | S22: 14815 | T22: =G22+R22 -> 2526852 | U22: =H22+S22 -> 202148 | V22: =O22-G22-R22 -> 0 | W22: =P22-H22-S22 -> 0
... A25: 1C24TUV | B25: 510 | C25: 03/10/2024 | D25: 0313878152 | E25: CÔNG TY TNHH XÂY DỰNG VÀ SẢN XUẤT CAO MINH | F25: 14/7 Đường TL 42, phường Thạnh Lộc, Quận 12, Thành phố Hồ Chí Minh, Việt Nam | G25: 2367296 | H25: 189384 | I25: 2556680 | J25: Hóa đơn đã bị điều chỉnh | K25: 241002GFV5GHRS | L25: Shopee | M25: BHHS2024006027 | O25: 2573148 | P25: 205852 | Q25: 00002582 | R25: 205852 | S25: 16468 | T25: =G25+R25 -> 2573148 | U25: =H25+S25 -> 205852 | V25: =O25-G25-R25 -> 0 | W25: =P25-H25-S25 -> 0
A26: 1C24TUV | B26: 511 | C26: 04/10/2024 | D26: 2300720588 | E26: CÔNG TY TNHH SẢN XUẤT VÀ THƯƠNG MẠI DAVIMAX | F26: Khu Bồ Sơn, Phường Võ Cường, Thành phố Bắc Ninh, Tỉnh Bắc Ninh, Việt Nam | G26: 14444444 | H26: 1155556 | I26: 15600000 | J26: Hóa đơn mới | K26: HD007178 | L26: Ngoài sàn | M26: BHHN2024000038 | O26: 14444444 | P26: 1155556 | V26: =O26-G26-R26 -> 0 | W26: =P26-H26-S26 -> 0
A27: 1C24TUV | B27: 514 | C27: 09/10/2024 | D27: 0318008787 | E27: CÔNG TY TNHH SẢN XUẤT NAVIS VIỆT NAM | F27: L3, Tòa nhà Vạn Đạt, Đường số 8, Lô II-1, Nhóm CN II, Khu Công Nghiệp Tân Bình, Phường Tây Thạnh, Quận Tân phú, Thành phố Hồ Chí Minh, Việt Nam | G27: 7738889 | H27: 619111 | I27: 8358000 | J27: Hóa đơn mới | K27: HD007220 | L27: Ngoài sàn | M27: BHHN2024000034 | O27: 7738889 | P27: 619111 | V27: =O27-G27-R27 -> 0 | W27: =P27-H27-S27 -> 0
A28: 1C24TUV | B28: 515 | C28: 09/10/2024 | D28: 6001628711 | E28: CÔNG TY TNHH TÀI LINH LAND | F28: Số 10 Lê Thị Hồng Gấm, Phường Tân An, TP.Buôn Ma Thuột, Tỉnh Đắk Lắk, Việt Nam | G28: 2399167 | H28: 191933 | I28: 2591100 | J28: Hóa đơn đã bị điều chỉnh | K28: 241004MWDA8FXT | L28: Shopee | M28: BHHS2024006068 | O28: 2665741 | P28: 213259 | Q28: 00002583 | R28: 266574 | S28: 21326 | T28: =G28+R28 -> 2665741 | U28: =H28+S28 -> 213259 | V28: =O28-G28-R28 -> 0 | W28: =P28-H28-S28 -> 0
A29: 1C24TUV | B29: 516 | C29: 14/10/2024 | D29: 0318522093 | E29: CÔNG TY TNHH SX VÀ TMDV ĐỒNG XU KỶ NIỆM ZINO | F29: 150/3 Lê Lợi, Phường 4, Quận Gò Vấp, Thành phố Hồ Chí Minh, Việt Nam | G29: 2202778 | H29: 176222 | I29: 2379000 | J29: Hóa đơn đã bị điều chỉnh | K29: 579455986800364255 | L29: Tiktok | M29: BHHT2024018921 | O29: 2573148 | P29: 205852 | Q29: 00002628 | R29: 370370 | S29: 29630 | T29: =G29+R29 -> 2573148 | U29: =H29+S29 -> 205852 | V29: =O29-G29-R29 -> 0 | W29: =P29-H29-S29 -> 0
A30: 1C24TUV | B30: 517 | C30: 14/10/2024 | D30: 3301719675 | E30: CÔNG TY TNHH THIẾT KẾ VÀ THI CÔNG CÔNG TRÌNH AHA HUẾ | F30: Tổ 4, KV2, Phường An Tây, Thành phố Huế, Tỉnh Thừa Thiên - Huế, Việt Nam | G30: 1702778 | H30: 136222 | I30: 1839000 | J30: Hóa đơn mới | K30: 2410095FR7Q45U | L30: Shopee | M30: BHHS2024006199 | O30: 1702778 | P30: 136222 | V30: =O30-G30-R30 -> 0 | W30: =P30-H30-S30 -> 0
A31: 1C24TUV | B31: 518 | C31: 14/10/2024 | D31: 0101976905 | E31: CÔNG TY CỔ PHẦN TẬP ĐOÀN SUNHOUSE | F31: Số 139, phố Nguyễn Thái Học, Phường Điện Biên, Quận Ba Đình, Thành phố Hà Nội, Việt Nam | G31: 846593 | H31: 67727 | I31: 914320 | J31: Hóa đơn đã bị điều chỉnh | K31: 240925TVHWC5UR | L31: Shopee | M31: BHHS2024005808 | O31: 962037 | P31: 76963 | Q31: 00002584 | R31: 115444 | S31: 9236 | T31: =G31+R31 -> 962037 | U31: =H31+S31 -> 76963 | V31: =O31-G31-R31 -> 0 | W31: =P31-H31-S31 -> 0
A32: 1C24TUV | B32: 523 | C32: 16/10/2024 | D32: 0314404490 | E32: CÔNG TY TNHH THƯƠNG MẠI DỊCH VỤ DIGI-TRAN | F32: Tầng 14, Tòa Nhà HM Town, 412 Nguyễn Thị Minh Khai, Phường 05, Quận 3, Thành phố Hồ Chí Minh, Việt Nam | G32: 1532500 | H32: 122600 | I32: 1655100 | J32: Hóa đơn đã bị điều chỉnh | K32: 2410107PP4B0UR | L32: Shopee | M32: BHHS2024006394 | O32: 1702778 | P32: 136222 | Q32: 00002586 | R32: 170278 | S32: 13622 | T32: =G32+R32 -> 1702778 | U32: =H32+S32 -> 136222 | V32: =O32-G32-R32 -> 0 | W32: =P32-H32-S32 -> 0
A33: 1C24TUV | B33: 524 | C33: 16/10/2024 | D33: 1801510068 | E33: CÔNG TY TNHH THƯƠNG MẠI DỊCH VỤ DU LỊCH TÀI PHƯỚC THÀNH | F33: 412/2 A, Cách Mạng Tháng Tám, Phường Bùi Hữu Nghĩa, Quận Bình Thuỷ, Thành phố Cần Thơ, Việt Nam | G33: 2283333 | H33: 182667 | I33: 2466000 | J33: Hóa đơn đã bị điều chỉnh | K33: 579465803582245741 | L33: Tiktok | M33: BHHT2024018495 | O33: 2515185 | P33: 201215 | Q33: 00002629 | R33: 231852 | S33: 18548 | T33: =G33+R33 -> 2515185 | U33: =H33+S33 -> 201215 | V33: =O33-G33-R33 -> 0 | W33: =P33-H33-S33 -> 0
A34: 1C24TUV | B34: 526 | C34: 17/10/2024 | D34: 0315568491 | E34: CÔNG TY TNHH DU LỊCH & SỰ KIỆN PHƯỢNG HOÀNG | F34: VP 02, Tầng 10, Tòa nhà Pearl Plaza, Số 561A Điện Biên Phủ, Phường 25, Quận Bình Thạnh, Thành phố Hồ Chí Minh, Việt Nam | G34: 1532500 | H34: 122600 | I34: 1655100 | J34: Hóa đơn đã bị điều chỉnh | K34: 579481957643422099 | L34: Tiktok | M34: BHHT2024018174 | O34: 1702778 | P34: 136222 | Q34: 00002630 | R34: 170278 | S34: 13622 | T34: =G34+R34 -> 1702778 | U34: =H34+S34 -> 136222 | V34: =O34-G34-R34 -> 0 | W34: =P34-H34-S34 -> 0
A35: 1C24TUV | B35: 530 | C35: 21/10/2024 | D35: 0318344789 | E35: CÔNG TY CỔ PHẦN DU LỊCH VÀ ĐẦU TƯ MELI CLUB | F35: Tòa Dreamplex, 195 Điện Biên Phủ, Phường 15, Quận Bình Thạnh, Thành phố Hồ Chí Minh, Việt Nam | G35: 846593 | H35: 67727 | I35: 914320 | J35: Hóa đơn đã bị điều chỉnh | K35: 579488501531839187 | L35: Tiktok | M35: BHHT2024017750 | O35: 962037 | P35: 76963 | Q35: 00002631 | R35: 115444 | S35: 9236 | T35: =G35+R35 -> 962037 | U35: =H35+S35 -> 76963 | V35: =O35-G35-R35 -> 0 | W35: =P35-H35-S35 -> 0
A36: 1C24TUV | B36: 531 | C36: 21/10/2024 | D36: 0314404490 | E36: CÔNG TY TNHH THƯƠNG MẠI DỊCH VỤ DIGI-TRAN | F36: Tầng 14, Tòa Nhà HM Town, 412 Nguyễn Thị Minh Khai, Phường 05, Quận 3, Thành phố Hồ Chí Minh, Việt Nam | G36: 1517593 | H36: 121407 | I36: 1639000 | J36: Hóa đơn đã bị điều chỉnh | K36: 241014GHX7TNKV | L36: Shopee | M36: BHHS2024006521 | O36: 1702778 | P36: 136222 | Q36: 00002587 | R36: 185185 | S36: 14815 | T36: =G36+R36 -> 1702778 | U36: =H36+S36 -> 136222 | V36: =O36-G36-R36 -> 0 | W36: =P36-H36-S36 -> 0
A37: 1C24TUV | B37: 534 | C37: 22/10/2024 | D37: 0109997537 | E37: CÔNG TY TNHH DỊCH VỤ TRUYỀN THÔNG DTC | F37: Số nhà 21A, ngách 56, ngõ 79 đường Cầu Giấy, tổ 3, Phường Yên Hoà, Quận Cầu Giấy, Thành phố Hà Nội, Việt Nam | G37: 2026556 | H37: 162124 | I37: 2188680 | J37: Hóa đơn đã bị điều chỉnh | K37: 579487419366476134 | L37: Tiktok | M37: BHHT2024017692 | O37: 2202778 | P37: 176222 | Q37: 00002642 | R37: 176222 | S37: 14098 | T37: =G37+R37 -> 2202778 | U37: =H37+S37 -> 176222 | V37: =O37-G37-R37 -> 0 | W37: =P37-H37-S37 -> 0
A38: 1C24TUV | B38: 538 | C38: 26/10/2024 | D38: 0304295429 | E38: CÔNG TY TNHH INTEL PRODUCTS VIỆT NAM | F38: Lô I2, đường D1, khu công nghệ cao, Phường Tân Phú, Thành phố Thủ Đức, Thành phố Hồ Chí Minh, Việt Nam | G38: 1531037 | H38: 122483 | I38: 1653520 | J38: Hóa đơn đã bị điều chỉnh | K38: 2409298GGY2ADN | L38: Shopee | M38: BHHS2024005949 | O38: 1739815 | P38: 139185 | Q38: 00002588 | R38: 208778 | S38: 16702 | T38: =G38+R38 -> 1739815 | U38: =H38+S38 -> 139185 | V38: =O38-G38-R38 -> 0 | W38: =P38-H38-S38 -> 0
A39: 1C24TUV | B39: 539 | C39: 30/10/2024 | D39: 0318232274 | E39: CÔNG TY TNHH TRUYỀN THÔNG VÀ SỰ KIỆN NEW SKY | F39: 146/10/9 Tô Ký, phường Đông Hưng Thuận, Quận 12, Thành phố Hồ Chí Minh, Việt Nam | G39: 2187176 | H39: 174974 | I39: 2362150 | J39: Hóa đơn đã bị điều chỉnh | K39: 579489105018194942 | L39: Tiktok | M39: BHHT2024017794 | O39: 2573148 | P39: 205852 | Q39: 00002633 | R39: 385972 | S39: 30878 | T39: =G39+R39 -> 2573148 | U39: =H39+S39 -> 205852 | V39: =O39-G39-R39 -> 0 | W39: =P39-H39-S39 -> 0
A40: 1C24TUV | B40: 540 | C40: 30/10/2024 | D40: 0315259091 | E40: CÔNG TY TNHH HUGE-FAM | F40: 27B Nguyễn Đình Chiểu, Phường Đa Kao, Quận 1, Thành phố Hồ Chí Minh, Việt Nam | G40: 443519 | H40: 35482 | I40: 479001 | J40: Hóa đơn mới | K40: 241029SCHU3H27 | L40: Shopee | M40: BHHS2024007139 | O40: 443519 | P40: 35481 | V40: =O40-G40-R40 -> 0 | W40: =P40-H40-S40 -> -1
A41: 1C24TUV | B41: 541 | C41: 30/10/2024 | D41: 3702501637 | E41: CÔNG TY TNHH HI-LEVEL ENTERPRISE | F41: Lô B7 Khu công nghiệp Đại Đăng, Phường Phú Tân, Thành phố Thủ Dầu Một, Tỉnh Bình Dương, Việt Nam | G41: 834907 | H41: 66793 | I41: 901700 | J41: Hóa đơn đã bị điều chỉnh | K41: 579523460756113690 | L41: Tiktok | M41: BHHT2024017301 | O41: 803704 | P41: 64296 | Q41: 00002634 | R41: -31203 | S41: -2496 | T41: =G41+R41 -> 803704 | U41: =H41+S41 -> 64297 | V41: =O41-G41-R41 -> 0 | W41: =P41-H41-S41 -> -1
A42: 1C24TUV | B42: 542 | C42: 30/10/2024 | D42: 0401699508 | E42: CÔNG TY TNHH MỘT THÀNH VIÊN PHẠM NGÂN NHI | F42: 170 Võ Nguyên Giáp, Phường Phước Mỹ, Quận Sơn Trà, Thành phố Đà Nẵng, Việt Nam | G42: 4035185 | H42: 322815 | I42: 4358000 | J42: Hóa đơn mới | K42: 579522212693182576 | L42: Tiktok | M42: BHHT2024022346 | O42: 4035185 | P42: 322815 | V42: =O42-G42-R42 -> 0 | W42: =P42-H42-S42 -> 0
...

Sheet F0, F1, F2, ...
A1: F0 — Hóa đơn gốc | H1: F1 — Điều chỉnh | N1: F2 — Điều chỉnh | T1: F3 — Điều chỉnh | Z1: Giá trị cộng dồn và kiểm tra | AD1: F4 — Hóa đơn dự kiến tạo | AJ1: F5 — Hóa đơn dự kiến tạo | AP1: F6 — Hóa đơn dự kiến tạo | AV1: F7 — Hóa đơn dự kiến tạo | BB1: Cộng dồn sau F4–F7 (dự kiến)
A2: Ký hiệu | B2: Năm | C2: Số hóa đơn | D2: Ngày | E2: Tiền hàng | F2: Thuế | G2: Thanh toán | H2: Ký hiệu 1 | I2: Số hóa đơn 1 | J2: Ngày 1 | K2: Tiền hàng 1 | L2: Thuế 1 | M2: Thanh toán 1 | N2: Ký hiệu 2 | O2: Số hóa đơn 2 | P2: Ngày 2 | Q2: Tiền hàng 2 | R2: Thuế 2 | S2: Thanh toán 2 | T2: Ký hiệu 3 | U2: Số hóa đơn 3 | V2: Ngày 3 | W2: Tiền hàng 3 | X2: Thuế 3 | Y2: Thanh toán 3 | Z2: Cộng dồn tiền hàng | AA2: Cộng dồn thuế | AB2: Cộng dồn thanh toán | AC2: Cần kiểm tra | AD2: Nội dung F4 / HĐ tham chiếu | AE2: Số HĐ mới F4 | AF2: Ngày HĐ mới F4 | AG2: Tiền hàng F4 | AH2: Thuế F4 | AI2: Thanh toán F4 | AJ2: Nội dung F5 / HĐ tham chiếu | AK2: Số HĐ mới F5 | AL2: Ngày HĐ mới F5 | AM2: Tiền hàng F5 | AN2: Thuế F5 | AO2: Thanh toán F5 | AP2: Nội dung F6 / HĐ tham chiếu | AQ2: Số HĐ mới F6 | AR2: Ngày HĐ mới F6 | AS2: Tiền hàng F6 | AT2: Thuế F6 | AU2: Thanh toán F6 | AV2: Nội dung F7 / HĐ tham chiếu | AW2: Số HĐ mới F7 | AX2: Ngày HĐ mới F7 | AY2: Tiền hàng F7 | AZ2: Thuế F7 | BA2: Thanh toán F7 | BB2: Cộng dồn tiền hàng sau dự kiến | BC2: Cộng dồn thuế sau dự kiến | BD2: Cộng dồn thanh toán sau dự kiến
A3: 1C24TUV | B3: {=INDEX('HD cty 2024'!B:B,MATCH('F0, F1, F2, ...'!$C3,'HD cty 2024'!B:B,0))} -> #N/A | C3: 3 | D3: 45301 | E3: 11334130 | F3: 906730 | G3: 12240860 | H3: 1C25TUV | I3: 00000508 | J3: 45773 | K3: -356085 | L3: -28487 | M3: -384572 | Z3: 10978045 | AA3: 878243 | AB3: 11856288 | AC3: Đã bổ sung theo chốt 19/10/2026; Giảm số lượng gốc, giữ đơn giá dương: 1C24TUV/00000003, STT 2033; Đảo khoản điều chỉnh cũ; chỉ đảo thành tiền, nguồn không có số lượng/đơn giá: 1C25TUV/00000508, STT 2034. | AD3: Giảm số lượng gốc, giữ đơn giá dương: 1C24TUV/00000003 — STT import 2033 | AF3: 46314 | AG3: -11334130 | AH3: -906730 | AI3: -12240860 | AJ3: Đảo khoản điều chỉnh cũ; chỉ đảo thành tiền, nguồn không có số lượng/đơn giá: 1C25TUV/00000508 — STT import 2034 | AL3: 46314 | AM3: 356085 | AN3: 28487 | AO3: 384572 | BB3: =SUM(Z3,AG3,AM3,AS3,AY3) -> 0 | BC3: =SUM(AA3,AH3,AN3,AT3,AZ3) -> 0 | BD3: =SUM(AB3,AI3,AO3,AU3,BA3) -> 0
A4: 1C24TUV | B4: {=INDEX('HD cty 2024'!B:B,MATCH('F0, F1, F2, ...'!$C4,'HD cty 2024'!B:B,0))} -> #N/A | C4: 4 | D4: 45301 | E4: 32002666 | F4: 2560213 | G4: 34562879 | H4: 1C25TUV | I4: 00000784 | J4: 45801 | K4: 2147334 | L4: 171787 | M4: 2319121 | Z4: 34150000 | AA4: 2732000 | AB4: 36882000 | AD4: Đảo khoản 1C25TUV/00000784; tham chiếu gốc 1C24TUV/00000004 | AG4: -2147334 | AH4: -171787 | AI4: -2319121 | AJ4: Giảm toàn bộ gốc: 1C24TUV/00000004 | AM4: -32002666 | AN4: -2560213 | AO4: -34562879 | BB4: =IF(AND(ISNUMBER(Z4),COUNT(AG4,AM4,AS4,AY4)=2),Z4+SUM(AG4,AM4,AS4,AY4),"") -> 0 | BC4: =IF(AND(ISNUMBER(AA4),COUNT(AH4,AN4,AT4,AZ4)=2),AA4+SUM(AH4,AN4,AT4,AZ4),"") -> 0 | BD4: =IF(AND(ISNUMBER(AB4),COUNT(AI4,AO4,AU4,BA4)=2),AB4+SUM(AI4,AO4,AU4,BA4),"") -> 0
A5: 1C24TUV | B5: {=INDEX('HD cty 2024'!B:B,MATCH('F0, F1, F2, ...'!$C5,'HD cty 2024'!B:B,0))} -> #N/A | C5: 5 | D5: 45301 | E5: 29093426 | F5: 2327474 | G5: 31420900 | H5: 1C25TUV | I5: 00000785 | J5: 45801 | K5: 1541759 | L5: 123341 | M5: 1665100 | Z5: 30635185 | AA5: 2450815 | AB5: 33086000 | AD5: Đảo khoản 1C25TUV/00000785; tham chiếu gốc 1C24TUV/00000005 | AG5: -1541759 | AH5: -123341 | AI5: -1665100 | AJ5: Giảm toàn bộ gốc: 1C24TUV/00000005 | AM5: -29093426 | AN5: -2327474 | AO5: -31420900 | BB5: =IF(AND(ISNUMBER(Z5),COUNT(AG5,AM5,AS5,AY5)=2),Z5+SUM(AG5,AM5,AS5,AY5),"") -> 0 | BC5: =IF(AND(ISNUMBER(AA5),COUNT(AH5,AN5,AT5,AZ5)=2),AA5+SUM(AH5,AN5,AT5,AZ5),"") -> 0 | BD5: =IF(AND(ISNUMBER(AB5),COUNT(AI5,AO5,AU5,BA5)=2),AB5+SUM(AI5,AO5,AU5,BA5),"") -> 0
A6: 1C24TUV | B6: {=INDEX('HD cty 2024'!B:B,MATCH('F0, F1, F2, ...'!$C6,'HD cty 2024'!B:B,0))} -> #N/A | C6: 6 | D6: 45307 | E6: 8257501 | F6: 660600 | G6: 8918101 | H6: 1C25TUV | I6: 00000786 | J6: 45801 | K6: 543425 | L6: 43474 | M6: 586899 | Z6: 8800926 | AA6: 704074 | AB6: 9505000 | AD6: Đảo khoản 1C25TUV/00000786; tham chiếu gốc 1C24TUV/00000006 | AG6: -543425 | AH6: -43474 | AI6: -586899 | AJ6: Giảm toàn bộ gốc: 1C24TUV/00000006 | AM6: -8257501 | AN6: -660600 | AO6: -8918101 | BB6: =IF(AND(ISNUMBER(Z6),COUNT(AG6,AM6,AS6,AY6)=2),Z6+SUM(AG6,AM6,AS6,AY6),"") -> 0 | BC6: =IF(AND(ISNUMBER(AA6),COUNT(AH6,AN6,AT6,AZ6)=2),AA6+SUM(AH6,AN6,AT6,AZ6),"") -> 0 | BD6: =IF(AND(ISNUMBER(AB6),COUNT(AI6,AO6,AU6,BA6)=2),AB6+SUM(AI6,AO6,AU6,BA6),"") -> 0
A7: 1C24TUV | B7: {=INDEX('HD cty 2024'!B:B,MATCH('F0, F1, F2, ...'!$C7,'HD cty 2024'!B:B,0))} -> #N/A | C7: 7 | D7: 45307 | E7: 23677893 | F7: 1894231 | G7: 25572124 | H7: 1C25TUV | I7: 00000812 | J7: 45802 | K7: -485300 | L7: -38824 | M7: -524124 | Z7: 23192593 | AA7: 1855407 | AB7: 25048000 | AD7: Đảo khoản 1C25TUV/00000812; tham chiếu gốc 1C24TUV/00000007 | AG7: 485300 | AH7: 38824 | AI7: 524124 | AJ7: Giảm toàn bộ gốc: 1C24TUV/00000007 | AM7: -23677893 | AN7: -1894231 | AO7: -25572124 | BB7: =IF(AND(ISNUMBER(Z7),COUNT(AG7,AM7,AS7,AY7)=2),Z7+SUM(AG7,AM7,AS7,AY7),"") -> 0 | BC7: =IF(AND(ISNUMBER(AA7),COUNT(AH7,AN7,AT7,AZ7)=2),AA7+SUM(AH7,AN7,AT7,AZ7),"") -> 0 | BD7: =IF(AND(ISNUMBER(AB7),COUNT(AI7,AO7,AU7,BA7)=2),AB7+SUM(AI7,AO7,AU7,BA7),"") -> 0
A8: 1C24TUV | B8: {=INDEX('HD cty 2024'!B:B,MATCH('F0, F1, F2, ...'!$C8,'HD cty 2024'!B:B,0))} -> #N/A | C8: 8 | D8: 45307 | E8: 27250819 | F8: 2180066 | G8: 29430885 | H8: 1C25TUV | I8: 00000813 | J8: 45802 | K8: -3474893 | L8: -277991 | M8: -3752884 | Z8: 23775926 | AA8: 1902075 | AB8: 25678001 | AD8: Đảo khoản 1C25TUV/00000813; tham chiếu gốc 1C24TUV/00000008 | AG8: 3474893 | AH8: 277991 | AI8: 3752884 | AJ8: Giảm toàn bộ gốc: 1C24TUV/00000008 | AM8: -27250819 | AN8: -2180066 | AO8: -29430885 | BB8: =IF(AND(ISNUMBER(Z8),COUNT(AG8,AM8,AS8,AY8)=2),Z8+SUM(AG8,AM8,AS8,AY8),"") -> 0 | BC8: =IF(AND(ISNUMBER(AA8),COUNT(AH8,AN8,AT8,AZ8)=2),AA8+SUM(AH8,AN8,AT8,AZ8),"") -> 0 | BD8: =IF(AND(ISNUMBER(AB8),COUNT(AI8,AO8,AU8,BA8)=2),AB8+SUM(AI8,AO8,AU8,BA8),"") -> 0
A9: 1C24TUV | B9: {=INDEX('HD cty 2024'!B:B,MATCH('F0, F1, F2, ...'!$C9,'HD cty 2024'!B:B,0))} -> #N/A | C9: 9 | D9: 45307 | E9: 19665616 | F9: 1573249 | G9: 21238865 | H9: 1C25TUV | I9: 00000814 | J9: 45802 | K9: -1422535 | L9: -113803 | M9: -1536338 | Z9: 18243081 | AA9: 1459446 | AB9: 19702527 | AD9: Đảo khoản 1C25TUV/00000814; tham chiếu gốc 1C24TUV/00000009 | AG9: 1422535 | AH9: 113803 | AI9: 1536338 | AJ9: Giảm toàn bộ gốc: 1C24TUV/00000009 | AM9: -19665616 | AN9: -1573249 | AO9: -21238865 | BB9: =IF(AND(ISNUMBER(Z9),COUNT(AG9,AM9,AS9,AY9)=2),Z9+SUM(AG9,AM9,AS9,AY9),"") -> 0 | BC9: =IF(AND(ISNUMBER(AA9),COUNT(AH9,AN9,AT9,AZ9)=2),AA9+SUM(AH9,AN9,AT9,AZ9),"") -> 0 | BD9: =IF(AND(ISNUMBER(AB9),COUNT(AI9,AO9,AU9,BA9)=2),AB9+SUM(AI9,AO9,AU9,BA9),"") -> 0
A10: 1C24TUV | B10: {=INDEX('HD cty 2024'!B:B,MATCH('F0, F1, F2, ...'!$C10,'HD cty 2024'!B:B,0))} -> #N/A | C10: 10 | D10: 45307 | E10: 42723469 | F10: 3417878 | G10: 46141347 | H10: 1C25TUV | I10: 00002606 | J10: 45808 | K10: 1960615 | L10: 156849 | M10: 2117464 | Z10: 44684084 | AA10: 3574727 | AB10: 48258811 | AD10: Đảo khoản 1C25TUV/00002606; tham chiếu gốc 1C24TUV/00000010 | AG10: -1960615 | AH10: -156849 | AI10: -2117464 | AJ10: Giảm toàn bộ gốc: 1C24TUV/00000010 | AM10: -42723469 | AN10: -3417878 | AO10: -46141347 | BB10: =IF(AND(ISNUMBER(Z10),COUNT(AG10,AM10,AS10,AY10)=2),Z10+SUM(AG10,AM10,AS10,AY10),"") -> 0 | BC10: =IF(AND(ISNUMBER(AA10),COUNT(AH10,AN10,AT10,AZ10)=2),AA10+SUM(AH10,AN10,AT10,AZ10),"") -> 0 | BD10: =IF(AND(ISNUMBER(AB10),COUNT(AI10,AO10,AU10,BA10)=2),AB10+SUM(AI10,AO10,AU10,BA10),"") -> 0
A11: 1C24TUV | B11: {=INDEX('HD cty 2024'!B:B,MATCH('F0, F1, F2, ...'!$C11,'HD cty 2024'!B:B,0))} -> #N/A | C11: 11 | D11: 45307 | E11: 6000325 | F11: 480026 | G11: 6480351 | H11: 1C25TUV | I11: 00000509 | J11: 45773 | K11: -355562 | L11: -28445 | M11: -384007 | Z11: 5644763 | AA11: 451581 | AB11: 6096344 | AD11: Đảo khoản 1C25TUV/00000509; tham chiếu gốc 1C24TUV/00000011 | AG11: 355562 | AH11: 28445 | AI11: 384007 | AJ11: Giảm toàn bộ gốc: 1C24TUV/00000011 | AM11: -6000325 | AN11: -480026 | AO11: -6480351 | BB11: =IF(AND(ISNUMBER(Z11),COUNT(AG11,AM11,AS11,AY11)=2),Z11+SUM(AG11,AM11,AS11,AY11),"") -> 0 | BC11: =IF(AND(ISNUMBER(AA11),COUNT(AH11,AN11,AT11,AZ11)=2),AA11+SUM(AH11,AN11,AT11,AZ11),"") -> 0 | BD11: =IF(AND(ISNUMBER(AB11),COUNT(AI11,AO11,AU11,BA11)=2),AB11+SUM(AI11,AO11,AU11,BA11),"") -> 0
A12: 1C24TUV | B12: {=INDEX('HD cty 2024'!B:B,MATCH('F0, F1, F2, ...'!$C12,'HD cty 2024'!B:B,0))} -> #N/A | C12: 12 | D12: 45307 | E12: 43046669 | F12: 3443734 | G12: 46490403 | H12: 1C25TUV | I12: 00000815 | J12: 45802 | K12: -1402538 | L12: -112203 | M12: -1514741 | Z12: 41644131 | AA12: 3331531 | AB12: 44975662 | AD12: Đảo khoản 1C25TUV/00000815; tham chiếu gốc 1C24TUV/00000012 | AG12: 1402538 | AH12: 112203 | AI12: 1514741 | AJ12: Giảm toàn bộ gốc: 1C24TUV/00000012 | AM12: -43046669 | AN12: -3443734 | AO12: -46490403 | BB12: =IF(AND(ISNUMBER(Z12),COUNT(AG12,AM12,AS12,AY12)=2),Z12+SUM(AG12,AM12,AS12,AY12),"") -> 0 | BC12: =IF(AND(ISNUMBER(AA12),COUNT(AH12,AN12,AT12,AZ12)=2),AA12+SUM(AH12,AN12,AT12,AZ12),"") -> 0 | BD12: =IF(AND(ISNUMBER(AB12),COUNT(AI12,AO12,AU12,BA12)=2),AB12+SUM(AI12,AO12,AU12,BA12),"") -> 0
A13: 1C24TUV | B13: {=INDEX('HD cty 2024'!B:B,MATCH('F0, F1, F2, ...'!$C13,'HD cty 2024'!B:B,0))} -> #N/A | C13: 13 | D13: 45307 | E13: 68151637 | F13: 5452131 | G13: 73603768 | H13: 1C25TUV | I13: 00000816 | J13: 45802 | K13: 2917057 | L13: 233365 | M13: 3150422 | Z13: 71068694 | AA13: 5685496 | AB13: 76754190 | AD13: Đảo khoản 1C25TUV/00000816; tham chiếu gốc 1C24TUV/00000013 | AG13: -2917057 | AH13: -233365 | AI13: -3150422 | AJ13: Giảm toàn bộ gốc: 1C24TUV/00000013 | AM13: -68151637 | AN13: -5452131 | AO13: -73603768 | BB13: =IF(AND(ISNUMBER(Z13),COUNT(AG13,AM13,AS13,AY13)=2),Z13+SUM(AG13,AM13,AS13,AY13),"") -> 0 | BC13: =IF(AND(ISNUMBER(AA13),COUNT(AH13,AN13,AT13,AZ13)=2),AA13+SUM(AH13,AN13,AT13,AZ13),"") -> 0 | BD13: =IF(AND(ISNUMBER(AB13),COUNT(AI13,AO13,AU13,BA13)=2),AB13+SUM(AI13,AO13,AU13,BA13),"") -> 0
A14: 1C24TUV | B14: {=INDEX('HD cty 2024'!B:B,MATCH('F0, F1, F2, ...'!$C14,'HD cty 2024'!B:B,0))} -> #N/A | C14: 14 | D14: 45307 | E14: 97195166 | F14: 7775613 | G14: 104970779 | H14: 1C25TUV | I14: 00000817 | J14: 45802 | K14: 3082612 | L14: 246609 | M14: 3329221 | Z14: 100277778 | AA14: 8022222 | AB14: 108300000 | AD14: Đảo khoản 1C25TUV/00000817; tham chiếu gốc 1C24TUV/00000014 | AG14: -3082612 | AH14: -246609 | AI14: -3329221 | AJ14: Giảm toàn bộ gốc: 1C24TUV/00000014 | AM14: -97195166 | AN14: -7775613 | AO14: -104970779 | BB14: =IF(AND(ISNUMBER(Z14),COUNT(AG14,AM14,AS14,AY14)=2),Z14+SUM(AG14,AM14,AS14,AY14),"") -> 0 | BC14: =IF(AND(ISNUMBER(AA14),COUNT(AH14,AN14,AT14,AZ14)=2),AA14+SUM(AH14,AN14,AT14,AZ14),"") -> 0 | BD14: =IF(AND(ISNUMBER(AB14),COUNT(AI14,AO14,AU14,BA14)=2),AB14+SUM(AI14,AO14,AU14,BA14),"") -> 0
A15: 1C24TUV | B15: {=INDEX('HD cty 2024'!B:B,MATCH('F0, F1, F2, ...'!$C15,'HD cty 2024'!B:B,0))} -> #N/A | C15: 15 | D15: 45307 | E15: 93625335 | F15: 7490027 | G15: 101115362 | H15: 1C25TUV | I15: 00000818 | J15: 45802 | K15: 2004295 | L15: 160344 | M15: 2164639 | Z15: 95629630 | AA15: 7650371 | AB15: 103280001 | AD15: Đảo khoản 1C25TUV/00000818; tham chiếu gốc 1C24TUV/00000015 | AG15: -2004295 | AH15: -160344 | AI15: -2164639 | AJ15: Giảm toàn bộ gốc: 1C24TUV/00000015 | AM15: -93625335 | AN15: -7490027 | AO15: -101115362 | BB15: =IF(AND(ISNUMBER(Z15),COUNT(AG15,AM15,AS15,AY15)=2),Z15+SUM(AG15,AM15,AS15,AY15),"") -> 0 | BC15: =IF(AND(ISNUMBER(AA15),COUNT(AH15,AN15,AT15,AZ15)=2),AA15+SUM(AH15,AN15,AT15,AZ15),"") -> 0 | BD15: =IF(AND(ISNUMBER(AB15),COUNT(AI15,AO15,AU15,BA15)=2),AB15+SUM(AI15,AO15,AU15,BA15),"") -> 0
... A22: 1C24TUV | B22: {=INDEX('HD cty 2024'!B:B,MATCH('F0, F1, F2, ...'!$C22,'HD cty 2024'!B:B,0))} -> #N/A | C22: 25 | D22: 45316 | E22: 35717417 | F22: 2857393 | G22: 38574810 | H22: 1C25TUV | I22: 00000788 | J22: 45801 | K22: 2656657 | L22: 212533 | M22: 2869190 | Z22: 38374074 | AA22: 3069926 | AB22: 41444000 | AD22: Đảo khoản 1C25TUV/00000788; tham chiếu gốc 1C24TUV/00000025 | AG22: -2656657 | AH22: -212533 | AI22: -2869190 | AJ22: Giảm toàn bộ gốc: 1C24TUV/00000025 | AM22: -35717417 | AN22: -2857393 | AO22: -38574810 | BB22: =IF(AND(ISNUMBER(Z22),COUNT(AG22,AM22,AS22,AY22)=2),Z22+SUM(AG22,AM22,AS22,AY22),"") -> 0 | BC22: =IF(AND(ISNUMBER(AA22),COUNT(AH22,AN22,AT22,AZ22)=2),AA22+SUM(AH22,AN22,AT22,AZ22),"") -> 0 | BD22: =IF(AND(ISNUMBER(AB22),COUNT(AI22,AO22,AU22,BA22)=2),AB22+SUM(AI22,AO22,AU22,BA22),"") -> 0
A23: 1C24TUV | B23: {=INDEX('HD cty 2024'!B:B,MATCH('F0, F1, F2, ...'!$C23,'HD cty 2024'!B:B,0))} -> #N/A | C23: 26 | D23: 45316 | E23: 18519308 | F23: 1481545 | G23: 20000853 | H23: 1C25TUV | I23: 00000512 | J23: 45773 | K23: -577062 | L23: -46166 | M23: -623228 | N23: 1C25TUV | O23: 00002316 | P23: 45807 | Q23: -509259 | R23: -40741 | S23: -550000 | Z23: 17432987 | AA23: 1394638 | AB23: 18827625 | AD23: Đảo khoản 1C25TUV/00000512; tham chiếu gốc 1C24TUV/00000026 | AG23: 577062 | AH23: 46166 | AI23: 623228 | AJ23: Đảo khoản 1C25TUV/00002316; tham chiếu gốc 1C24TUV/00000026 | AM23: 509259 | AN23: 40741 | AO23: 550000 | AP23: Giảm toàn bộ gốc: 1C24TUV/00000026 | AS23: -18519308 | AT23: -1481545 | AU23: -20000853 | BB23: =IF(AND(ISNUMBER(Z23),COUNT(AG23,AM23,AS23,AY23)=3),Z23+SUM(AG23,AM23,AS23,AY23),"") -> 0 | BC23: =IF(AND(ISNUMBER(AA23),COUNT(AH23,AN23,AT23,AZ23)=3),AA23+SUM(AH23,AN23,AT23,AZ23),"") -> 0 | BD23: =IF(AND(ISNUMBER(AB23),COUNT(AI23,AO23,AU23,BA23)=3),AB23+SUM(AI23,AO23,AU23,BA23),"") -> 0
A24: 1C24TUV | B24: {=INDEX('HD cty 2024'!B:B,MATCH('F0, F1, F2, ...'!$C24,'HD cty 2024'!B:B,0))} -> #N/A | C24: 27 | D24: 45316 | E24: 25776463 | F24: 2062117 | G24: 27838580 | H24: 1C25TUV | I24: 00000789 | J24: 45801 | K24: 1217056 | L24: 97364 | M24: 1314420 | Z24: 26993519 | AA24: 2159481 | AB24: 29153000 | AD24: Đảo khoản 1C25TUV/00000789; tham chiếu gốc 1C24TUV/00000027 | AG24: -1217056 | AH24: -97364 | AI24: -1314420 | AJ24: Giảm toàn bộ gốc: 1C24TUV/00000027 | AM24: -25776463 | AN24: -2062117 | AO24: -27838580 | BB24: =IF(AND(ISNUMBER(Z24),COUNT(AG24,AM24,AS24,AY24)=2),Z24+SUM(AG24,AM24,AS24,AY24),"") -> 0 | BC24: =IF(AND(ISNUMBER(AA24),COUNT(AH24,AN24,AT24,AZ24)=2),AA24+SUM(AH24,AN24,AT24,AZ24),"") -> 0 | BD24: =IF(AND(ISNUMBER(AB24),COUNT(AI24,AO24,AU24,BA24)=2),AB24+SUM(AI24,AO24,AU24,BA24),"") -> 0
A25: 1C24TUV | B25: {=INDEX('HD cty 2024'!B:B,MATCH('F0, F1, F2, ...'!$C25,'HD cty 2024'!B:B,0))} -> #N/A | C25: 29 | D25: 45322 | E25: 17610388 | F25: 1408831 | G25: 19019219 | H25: 1C25TUV | I25: 00000517 | J25: 45773 | K25: -306867 | L25: -24551 | M25: -331418 | Z25: 17303521 | AA25: 1384280 | AB25: 18687801 | AD25: Đảo khoản 1C25TUV/00000517; tham chiếu gốc 1C24TUV/00000029 | AG25: 306867 | AH25: 24551 | AI25: 331418 | AJ25: Giảm toàn bộ gốc: 1C24TUV/00000029 | AM25: -17610388 | AN25: -1408831 | AO25: -19019219 | BB25: =IF(AND(ISNUMBER(Z25),COUNT(AG25,AM25,AS25,AY25)=2),Z25+SUM(AG25,AM25,AS25,AY25),"") -> 0 | BC25: =IF(AND(ISNUMBER(AA25),COUNT(AH25,AN25,AT25,AZ25)=2),AA25+SUM(AH25,AN25,AT25,AZ25),"") -> 0 | BD25: =IF(AND(ISNUMBER(AB25),COUNT(AI25,AO25,AU25,BA25)=2),AB25+SUM(AI25,AO25,AU25,BA25),"") -> 0
A26: 1C24TUV | B26: {=INDEX('HD cty 2024'!B:B,MATCH('F0, F1, F2, ...'!$C26,'HD cty 2024'!B:B,0))} -> #N/A | C26: 30 | D26: 45322 | E26: 32152932 | F26: 2572235 | G26: 34725167 | H26: 1C25TUV | I26: 00000791 | J26: 45801 | K26: 2961883 | L26: 236951 | M26: 3198834 | Z26: 35114815 | AA26: 2809186 | AB26: 37924001 | AD26: Đảo khoản 1C25TUV/00000791; tham chiếu gốc 1C24TUV/00000030 | AG26: -2961883 | AH26: -236951 | AI26: -3198834 | AJ26: Giảm toàn bộ gốc: 1C24TUV/00000030 | AM26: -32152932 | AN26: -2572235 | AO26: -34725167 | BB26: =IF(AND(ISNUMBER(Z26),COUNT(AG26,AM26,AS26,AY26)=2),Z26+SUM(AG26,AM26,AS26,AY26),"") -> 0 | BC26: =IF(AND(ISNUMBER(AA26),COUNT(AH26,AN26,AT26,AZ26)=2),AA26+SUM(AH26,AN26,AT26,AZ26),"") -> 0 | BD26: =IF(AND(ISNUMBER(AB26),COUNT(AI26,AO26,AU26,BA26)=2),AB26+SUM(AI26,AO26,AU26,BA26),"") -> 0
A27: 1C24TUV | B27: {=INDEX('HD cty 2024'!B:B,MATCH('F0, F1, F2, ...'!$C27,'HD cty 2024'!B:B,0))} -> #N/A | C27: 31 | D27: 45325 | E27: 26518307 | F27: 2121465 | G27: 28639772 | H27: 1C25TUV | I27: 00002607 | J27: 45808 | K27: 2774286 | L27: 221943 | M27: 2996229 | Z27: 29292593 | AA27: 2343408 | AB27: 31636001 | AD27: Đảo khoản 1C25TUV/00002607; tham chiếu gốc 1C24TUV/00000031 | AG27: -2774286 | AH27: -221943 | AI27: -2996229 | AJ27: Giảm toàn bộ gốc: 1C24TUV/00000031 | AM27: -26518307 | AN27: -2121465 | AO27: -28639772 | BB27: =IF(AND(ISNUMBER(Z27),COUNT(AG27,AM27,AS27,AY27)=2),Z27+SUM(AG27,AM27,AS27,AY27),"") -> 0 | BC27: =IF(AND(ISNUMBER(AA27),COUNT(AH27,AN27,AT27,AZ27)=2),AA27+SUM(AH27,AN27,AT27,AZ27),"") -> 0 | BD27: =IF(AND(ISNUMBER(AB27),COUNT(AI27,AO27,AU27,BA27)=2),AB27+SUM(AI27,AO27,AU27,BA27),"") -> 0
A28: 1C24TUV | B28: {=INDEX('HD cty 2024'!B:B,MATCH('F0, F1, F2, ...'!$C28,'HD cty 2024'!B:B,0))} -> #N/A | C28: 32 | D28: 45325 | E28: 47807398 | F28: 3824592 | G28: 51631990 | H28: 1C25TUV | I28: 00000794 | J28: 45801 | K28: 3019454 | L28: 241556 | M28: 3261010 | Z28: 50826852 | AA28: 4066148 | AB28: 54893000 | AD28: Đảo khoản 1C25TUV/00000794; tham chiếu gốc 1C24TUV/00000032 | AG28: -3019454 | AH28: -241556 | AI28: -3261010 | AJ28: Giảm toàn bộ gốc: 1C24TUV/00000032 | AM28: -47807398 | AN28: -3824592 | AO28: -51631990 | BB28: =IF(AND(ISNUMBER(Z28),COUNT(AG28,AM28,AS28,AY28)=2),Z28+SUM(AG28,AM28,AS28,AY28),"") -> 0 | BC28: =IF(AND(ISNUMBER(AA28),COUNT(AH28,AN28,AT28,AZ28)=2),AA28+SUM(AH28,AN28,AT28,AZ28),"") -> 0 | BD28: =IF(AND(ISNUMBER(AB28),COUNT(AI28,AO28,AU28,BA28)=2),AB28+SUM(AI28,AO28,AU28,BA28),"") -> 0
A29: 1C24TUV | B29: {=INDEX('HD cty 2024'!B:B,MATCH('F0, F1, F2, ...'!$C29,'HD cty 2024'!B:B,0))} -> #N/A | C29: 33 | D29: 45325 | E29: 42989657 | F29: 3439173 | G29: 46428830 | H29: 1C25TUV | I29: 00002559 | J29: 45808 | K29: 2032250 | L29: 162580 | M29: 2194830 | Z29: 45021907 | AA29: 3601753 | AB29: 48623660 | AD29: Đảo khoản 1C25TUV/00002559; tham chiếu gốc 1C24TUV/00000033 | AG29: -2032250 | AH29: -162580 | AI29: -2194830 | AJ29: Giảm toàn bộ gốc: 1C24TUV/00000033 | AM29: -42989657 | AN29: -3439173 | AO29: -46428830 | BB29: =IF(AND(ISNUMBER(Z29),COUNT(AG29,AM29,AS29,AY29)=2),Z29+SUM(AG29,AM29,AS29,AY29),"") -> 0 | BC29: =IF(AND(ISNUMBER(AA29),COUNT(AH29,AN29,AT29,AZ29)=2),AA29+SUM(AH29,AN29,AT29,AZ29),"") -> 0 | BD29: =IF(AND(ISNUMBER(AB29),COUNT(AI29,AO29,AU29,BA29)=2),AB29+SUM(AI29,AO29,AU29,BA29),"") -> 0
A30: 1C24TUV | B30: {=INDEX('HD cty 2024'!B:B,MATCH('F0, F1, F2, ...'!$C30,'HD cty 2024'!B:B,0))} -> #N/A | C30: 34 | D30: 45325 | E30: 40842829 | F30: 3267426 | G30: 44110255 | H30: 1C25TUV | I30: 00002608 | J30: 45808 | K30: 7617356 | L30: 609388 | M30: 8226744 | N30: 1C25TUV | O30: 00002643 | P30: 45808 | Q30: -3757407 | R30: -300593 | S30: -4058000 | Z30: 44702778 | AA30: 3576221 | AB30: 48278999 | AD30: Đảo khoản 1C25TUV/00002608; tham chiếu gốc 1C24TUV/00000034 | AG30: -7617356 | AH30: -609388 | AI30: -8226744 | AJ30: Đảo khoản 1C25TUV/00002643; tham chiếu gốc 1C24TUV/00000034 | AM30: 3757407 | AN30: 300593 | AO30: 4058000 | AP30: Giảm toàn bộ gốc: 1C24TUV/00000034 | AS30: -40842829 | AT30: -3267426 | AU30: -44110255 | BB30: =IF(AND(ISNUMBER(Z30),COUNT(AG30,AM30,AS30,AY30)=3),Z30+SUM(AG30,AM30,AS30,AY30),"") -> 0 | BC30: =IF(AND(ISNUMBER(AA30),COUNT(AH30,AN30,AT30,AZ30)=3),AA30+SUM(AH30,AN30,AT30,AZ30),"") -> 0 | BD30: =IF(AND(ISNUMBER(AB30),COUNT(AI30,AO30,AU30,BA30)=3),AB30+SUM(AI30,AO30,AU30,BA30),"") -> 0
A31: 1C24TUV | B31: {=INDEX('HD cty 2024'!B:B,MATCH('F0, F1, F2, ...'!$C31,'HD cty 2024'!B:B,0))} -> #N/A | C31: 35 | D31: 45325 | E31: 40743073 | F31: 3259446 | G31: 44002519 | H31: 1C25TUV | I31: 00000795 | J31: 45801 | K31: 4468038 | L31: 357443 | M31: 4825481 | Z31: 45211111 | AA31: 3616889 | AB31: 48828000 | AD31: Đảo khoản 1C25TUV/00000795; tham chiếu gốc 1C24TUV/00000035 | AG31: -4468038 | AH31: -357443 | AI31: -4825481 | AJ31: Giảm toàn bộ gốc: 1C24TUV/00000035 | AM31: -40743073 | AN31: -3259446 | AO31: -44002519 | BB31: =IF(AND(ISNUMBER(Z31),COUNT(AG31,AM31,AS31,AY31)=2),Z31+SUM(AG31,AM31,AS31,AY31),"") -> 0 | BC31: =IF(AND(ISNUMBER(AA31),COUNT(AH31,AN31,AT31,AZ31)=2),AA31+SUM(AH31,AN31,AT31,AZ31),"") -> 0 | BD31: =IF(AND(ISNUMBER(AB31),COUNT(AI31,AO31,AU31,BA31)=2),AB31+SUM(AI31,AO31,AU31,BA31),"") -> 0
A32: 1C24TUV | B32: {=INDEX('HD cty 2024'!B:B,MATCH('F0, F1, F2, ...'!$C32,'HD cty 2024'!B:B,0))} -> #N/A | C32: 36 | D32: 45325 | E32: 42218239 | F32: 3377459 | G32: 45595698 | H32: 1C25TUV | I32: 00001038 | J32: 45803 | K32: 3638377 | L32: 291070 | M32: 3929447 | Z32: 45856616 | AA32: 3668529 | AB32: 49525145 | AD32: Đảo khoản 1C25TUV/00001038; tham chiếu gốc 1C24TUV/00000036 | AG32: -3638377 | AH32: -291070 | AI32: -3929447 | AJ32: Giảm toàn bộ gốc: 1C24TUV/00000036 | AM32: -42218239 | AN32: -3377459 | AO32: -45595698 | BB32: =IF(AND(ISNUMBER(Z32),COUNT(AG32,AM32,AS32,AY32)=2),Z32+SUM(AG32,AM32,AS32,AY32),"") -> 0 | BC32: =IF(AND(ISNUMBER(AA32),COUNT(AH32,AN32,AT32,AZ32)=2),AA32+SUM(AH32,AN32,AT32,AZ32),"") -> 0 | BD32: =IF(AND(ISNUMBER(AB32),COUNT(AI32,AO32,AU32,BA32)=2),AB32+SUM(AI32,AO32,AU32,BA32),"") -> 0
A33: 1C24TUV | B33: {=INDEX('HD cty 2024'!B:B,MATCH('F0, F1, F2, ...'!$C33,'HD cty 2024'!B:B,0))} -> #N/A | C33: 37 | D33: 45325 | E33: 46638353 | F33: 3731068 | G33: 50369421 | H33: 1C25TUV | I33: 00000796 | J33: 45801 | K33: 2904240 | L33: 232339 | M33: 3136579 | Z33: 49542593 | AA33: 3963407 | AB33: 53506000 | AD33: Đảo khoản 1C25TUV/00000796; tham chiếu gốc 1C24TUV/00000037 | AG33: -2904240 | AH33: -232339 | AI33: -3136579 | AJ33: Giảm toàn bộ gốc: 1C24TUV/00000037 | AM33: -46638353 | AN33: -3731068 | AO33: -50369421 | BB33: =IF(AND(ISNUMBER(Z33),COUNT(AG33,AM33,AS33,AY33)=2),Z33+SUM(AG33,AM33,AS33,AY33),"") -> 0 | BC33: =IF(AND(ISNUMBER(AA33),COUNT(AH33,AN33,AT33,AZ33)=2),AA33+SUM(AH33,AN33,AT33,AZ33),"") -> 0 | BD33: =IF(AND(ISNUMBER(AB33),COUNT(AI33,AO33,AU33,BA33)=2),AB33+SUM(AI33,AO33,AU33,BA33),"") -> 0
A34: 1C24TUV | B34: {=INDEX('HD cty 2024'!B:B,MATCH('F0, F1, F2, ...'!$C34,'HD cty 2024'!B:B,0))} -> #N/A | C34: 38 | D34: 45326 | E34: 31063215 | F34: 2485057 | G34: 33548272 | H34: 1C25TUV | I34: 00000797 | J34: 45801 | K34: 1578452 | L34: 126276 | M34: 1704728 | Z34: 32641667 | AA34: 2611333 | AB34: 35253000 | AD34: Đảo khoản 1C25TUV/00000797; tham chiếu gốc 1C24TUV/00000038 | AG34: -1578452 | AH34: -126276 | AI34: -1704728 | AJ34: Giảm toàn bộ gốc: 1C24TUV/00000038 | AM34: -31063215 | AN34: -2485057 | AO34: -33548272 | BB34: =IF(AND(ISNUMBER(Z34),COUNT(AG34,AM34,AS34,AY34)=2),Z34+SUM(AG34,AM34,AS34,AY34),"") -> 0 | BC34: =IF(AND(ISNUMBER(AA34),COUNT(AH34,AN34,AT34,AZ34)=2),AA34+SUM(AH34,AN34,AT34,AZ34),"") -> 0 | BD34: =IF(AND(ISNUMBER(AB34),COUNT(AI34,AO34,AU34,BA34)=2),AB34+SUM(AI34,AO34,AU34,BA34),"") -> 0
A35: 1C24TUV | B35: {=INDEX('HD cty 2024'!B:B,MATCH('F0, F1, F2, ...'!$C35,'HD cty 2024'!B:B,0))} -> #N/A | C35: 39 | D35: 45326 | E35: 68490865 | F35: 5479269 | G35: 73970134 | H35: 1C25TUV | I35: 00001039 | J35: 45803 | K35: 5217126 | L35: 417370 | M35: 5634496 | Z35: 73707991 | AA35: 5896639 | AB35: 79604630 | AD35: Đảo khoản 1C25TUV/00001039; tham chiếu gốc 1C24TUV/00000039 | AG35: -5217126 | AH35: -417370 | AI35: -5634496 | AJ35: Giảm toàn bộ gốc: 1C24TUV/00000039 | AM35: -68490865 | AN35: -5479269 | AO35: -73970134 | BB35: =IF(AND(ISNUMBER(Z35),COUNT(AG35,AM35,AS35,AY35)=2),Z35+SUM(AG35,AM35,AS35,AY35),"") -> 0 | BC35: =IF(AND(ISNUMBER(AA35),COUNT(AH35,AN35,AT35,AZ35)=2),AA35+SUM(AH35,AN35,AT35,AZ35),"") -> 0 | BD35: =IF(AND(ISNUMBER(AB35),COUNT(AI35,AO35,AU35,BA35)=2),AB35+SUM(AI35,AO35,AU35,BA35),"") -> 0
A36: 1C24TUV | B36: {=INDEX('HD cty 2024'!B:B,MATCH('F0, F1, F2, ...'!$C36,'HD cty 2024'!B:B,0))} -> #N/A | C36: 40 | D36: 45327 | E36: 27631166 | F36: 2210493 | G36: 29841659 | H36: 1C25TUV | I36: 00000798 | J36: 45801 | K36: 606797 | L36: 48544 | M36: 655341 | Z36: 28237963 | AA36: 2259037 | AB36: 30497000 | AD36: Đảo khoản 1C25TUV/00000798; tham chiếu gốc 1C24TUV/00000040 | AG36: -606797 | AH36: -48544 | AI36: -655341 | AJ36: Giảm toàn bộ gốc: 1C24TUV/00000040 | AM36: -27631166 | AN36: -2210493 | AO36: -29841659 | BB36: =IF(AND(ISNUMBER(Z36),COUNT(AG36,AM36,AS36,AY36)=2),Z36+SUM(AG36,AM36,AS36,AY36),"") -> 0 | BC36: =IF(AND(ISNUMBER(AA36),COUNT(AH36,AN36,AT36,AZ36)=2),AA36+SUM(AH36,AN36,AT36,AZ36),"") -> 0 | BD36: =IF(AND(ISNUMBER(AB36),COUNT(AI36,AO36,AU36,BA36)=2),AB36+SUM(AI36,AO36,AU36,BA36),"") -> 0
A37: 1C24TUV | B37: {=INDEX('HD cty 2024'!B:B,MATCH('F0, F1, F2, ...'!$C37,'HD cty 2024'!B:B,0))} -> #N/A | C37: 41 | D37: 45327 | E37: 98810581 | F37: 7904846 | G37: 106715427 | H37: 1C25TUV | I37: 00001040 | J37: 45803 | K37: 10155477 | L37: 812438 | M37: 10967915 | Z37: 108966058 | AA37: 8717284 | AB37: 117683342 | AD37: Đảo khoản 1C25TUV/00001040; tham chiếu gốc 1C24TUV/00000041 | AG37: -10155477 | AH37: -812438 | AI37: -10967915 | AJ37: Giảm toàn bộ gốc: 1C24TUV/00000041 | AM37: -98810581 | AN37: -7904846 | AO37: -106715427 | BB37: =IF(AND(ISNUMBER(Z37),COUNT(AG37,AM37,AS37,AY37)=2),Z37+SUM(AG37,AM37,AS37,AY37),"") -> 0 | BC37: =IF(AND(ISNUMBER(AA37),COUNT(AH37,AN37,AT37,AZ37)=2),AA37+SUM(AH37,AN37,AT37,AZ37),"") -> 0 | BD37: =IF(AND(ISNUMBER(AB37),COUNT(AI37,AO37,AU37,BA37)=2),AB37+SUM(AI37,AO37,AU37,BA37),"") -> 0
A38: 1C24TUV | B38: {=INDEX('HD cty 2024'!B:B,MATCH('F0, F1, F2, ...'!$C38,'HD cty 2024'!B:B,0))} -> #N/A | C38: 42 | D38: 45327 | E38: 114508332 | F38: 9160667 | G38: 123668999 | H38: 1C25TUV | I38: 00001041 | J38: 45803 | K38: 10435187 | L38: 834815 | M38: 11270002 | Z38: 124943519 | AA38: 9995482 | AB38: 134939001 | AD38: Đảo khoản 1C25TUV/00001041; tham chiếu gốc 1C24TUV/00000042 | AG38: -10435187 | AH38: -834815 | AI38: -11270002 | AJ38: Giảm toàn bộ gốc: 1C24TUV/00000042 | AM38: -114508332 | AN38: -9160667 | AO38: -123668999 | BB38: =IF(AND(ISNUMBER(Z38),COUNT(AG38,AM38,AS38,AY38)=2),Z38+SUM(AG38,AM38,AS38,AY38),"") -> 0 | BC38: =IF(AND(ISNUMBER(AA38),COUNT(AH38,AN38,AT38,AZ38)=2),AA38+SUM(AH38,AN38,AT38,AZ38),"") -> 0 | BD38: =IF(AND(ISNUMBER(AB38),COUNT(AI38,AO38,AU38,BA38)=2),AB38+SUM(AI38,AO38,AU38,BA38),"") -> 0
A39: 1C24TUV | B39: {=INDEX('HD cty 2024'!B:B,MATCH('F0, F1, F2, ...'!$C39,'HD cty 2024'!B:B,0))} -> #N/A | C39: 43 | D39: 45327 | E39: 37291101 | F39: 2983288 | G39: 40274389 | H39: 1C25TUV | I39: 00000799 | J39: 45801 | K39: 1406121 | L39: 112490 | M39: 1518611 | Z39: 38697222 | AA39: 3095778 | AB39: 41793000 | AD39: Đảo khoản 1C25TUV/00000799; tham chiếu gốc 1C24TUV/00000043 | AG39: -1406121 | AH39: -112490 | AI39: -1518611 | AJ39: Giảm toàn bộ gốc: 1C24TUV/00000043 | AM39: -37291101 | AN39: -2983288 | AO39: -40274389 | BB39: =IF(AND(ISNUMBER(Z39),COUNT(AG39,AM39,AS39,AY39)=2),Z39+SUM(AG39,AM39,AS39,AY39),"") -> 0 | BC39: =IF(AND(ISNUMBER(AA39),COUNT(AH39,AN39,AT39,AZ39)=2),AA39+SUM(AH39,AN39,AT39,AZ39),"") -> 0 | BD39: =IF(AND(ISNUMBER(AB39),COUNT(AI39,AO39,AU39,BA39)=2),AB39+SUM(AI39,AO39,AU39,BA39),"") -> 0
A40: 1C24TUV | B40: {=INDEX('HD cty 2024'!B:B,MATCH('F0, F1, F2, ...'!$C40,'HD cty 2024'!B:B,0))} -> #N/A | C40: 44 | D40: 45327 | E40: 96242189 | F40: 7699375 | G40: 103941564 | H40: 1C25TUV | I40: 00001042 | J40: 45803 | K40: 9141607 | L40: 731329 | M40: 9872936 | Z40: 105383796 | AA40: 8430704 | AB40: 113814500 | AD40: Đảo khoản 1C25TUV/00001042; tham chiếu gốc 1C24TUV/00000044 | AG40: -9141607 | AH40: -731329 | AI40: -9872936 | AJ40: Giảm toàn bộ gốc: 1C24TUV/00000044 | AM40: -96242189 | AN40: -7699375 | AO40: -103941564 | BB40: =IF(AND(ISNUMBER(Z40),COUNT(AG40,AM40,AS40,AY40)=2),Z40+SUM(AG40,AM40,AS40,AY40),"") -> 0 | BC40: =IF(AND(ISNUMBER(AA40),COUNT(AH40,AN40,AT40,AZ40)=2),AA40+SUM(AH40,AN40,AT40,AZ40),"") -> 0 | BD40: =IF(AND(ISNUMBER(AB40),COUNT(AI40,AO40,AU40,BA40)=2),AB40+SUM(AI40,AO40,AU40,BA40),"") -> 0
A41: 1C24TUV | B41: {=INDEX('HD cty 2024'!B:B,MATCH('F0, F1, F2, ...'!$C41,'HD cty 2024'!B:B,0))} -> #N/A | C41: 45 | D41: 45327 | E41: 30080828 | F41: 2406466 | G41: 32487294 | H41: 1C25TUV | I41: 00001043 | J41: 45803 | K41: 3158072 | L41: 252646 | M41: 3410718 | Z41: 33238900 | AA41: 2659112 | AB41: 35898012 | AD41: Đảo khoản 1C25TUV/00001043; tham chiếu gốc 1C24TUV/00000045 | AG41: -3158072 | AH41: -252646 | AI41: -3410718 | AJ41: Giảm toàn bộ gốc: 1C24TUV/00000045 | AM41: -30080828 | AN41: -2406466 | AO41: -32487294 | BB41: =IF(AND(ISNUMBER(Z41),COUNT(AG41,AM41,AS41,AY41)=2),Z41+SUM(AG41,AM41,AS41,AY41),"") -> 0 | BC41: =IF(AND(ISNUMBER(AA41),COUNT(AH41,AN41,AT41,AZ41)=2),AA41+SUM(AH41,AN41,AT41,AZ41),"") -> 0 | BD41: =IF(AND(ISNUMBER(AB41),COUNT(AI41,AO41,AU41,BA41)=2),AB41+SUM(AI41,AO41,AU41,BA41),"") -> 0
A42: 1C24TUV | B42: {=INDEX('HD cty 2024'!B:B,MATCH('F0, F1, F2, ...'!$C42,'HD cty 2024'!B:B,0))} -> #N/A | C42: 46 | D42: 45327 | E42: 34366587 | F42: 2749327 | G42: 37115914 | H42: 1C25TUV | I42: 00001044 | J42: 45803 | K42: 2255635 | L42: 180451 | M42: 2436086 | Z42: 36622222 | AA42: 2929778 | AB42: 39552000 | AD42: Đảo khoản 1C25TUV/00001044; tham chiếu gốc 1C24TUV/00000046 | AG42: -2255635 | AH42: -180451 | AI42: -2436086 | AJ42: Giảm toàn bộ gốc: 1C24TUV/00000046 | AM42: -34366587 | AN42: -2749327 | AO42: -37115914 | BB42: =IF(AND(ISNUMBER(Z42),COUNT(AG42,AM42,AS42,AY42)=2),Z42+SUM(AG42,AM42,AS42,AY42),"") -> 0 | BC42: =IF(AND(ISNUMBER(AA42),COUNT(AH42,AN42,AT42,AZ42)=2),AA42+SUM(AH42,AN42,AT42,AZ42),"") -> 0 | BD42: =IF(AND(ISNUMBER(AB42),COUNT(AI42,AO42,AU42,BA42)=2),AB42+SUM(AI42,AO42,AU42,BA42),"") -> 0
... A67: 1C24TUV | B67: {=INDEX('HD cty 2024'!B:B,MATCH('F0, F1, F2, ...'!$C67,'HD cty 2024'!B:B,0))} -> #N/A | C67: 76 | D67: 45352 | E67: 41367500 | F67: 3309400 | G67: 44676900 | H67: 1C25TUV | I67: 00001161 | J67: 45803 | K67: 1175093 | L67: 94007 | M67: 1269100 | Z67: 42542593 | AA67: 3403407 | AB67: 45946000 | AD67: Đảo khoản 1C25TUV/00001161; tham chiếu gốc 1C24TUV/00000076 | AG67: -1175093 | AH67: -94007 | AI67: -1269100 | AJ67: Giảm toàn bộ gốc: 1C24TUV/00000076 | AM67: -41367500 | AN67: -3309400 | AO67: -44676900 | BB67: =IF(AND(ISNUMBER(Z67),COUNT(AG67,AM67,AS67,AY67)=2),Z67+SUM(AG67,AM67,AS67,AY67),"") -> 0 | BC67: =IF(AND(ISNUMBER(AA67),COUNT(AH67,AN67,AT67,AZ67)=2),AA67+SUM(AH67,AN67,AT67,AZ67),"") -> 0 | BD67: =IF(AND(ISNUMBER(AB67),COUNT(AI67,AO67,AU67,BA67)=2),AB67+SUM(AI67,AO67,AU67,BA67),"") -> 0
A68: 1C24TUV | B68: {=INDEX('HD cty 2024'!B:B,MATCH('F0, F1, F2, ...'!$C68,'HD cty 2024'!B:B,0))} -> #N/A | C68: 77 | D68: 45352 | E68: 50252655 | F68: 4020212 | G68: 54272867 | H68: 1C24TUV | I68: 00000186 | J68: 45408 | K68: -22287360 | L68: -1782989 | M68: -24070349 | N68: 1C25TUV | O68: 00002599 | P68: 45808 | Q68: 2758779 | R68: 220702 | S68: 2979481 | Z68: 30724074 | AA68: 2457925 | AB68: 33181999 | AD68: Đảo khoản 1C24TUV/00000186; tham chiếu gốc 1C24TUV/00000077 | AG68: 22287360 | AH68: 1782989 | AI68: 24070349 | AJ68: Đảo khoản 1C25TUV/00002599; tham chiếu gốc 1C24TUV/00000077 | AM68: -2758779 | AN68: -220702 | AO68: -2979481 | AP68: Giảm toàn bộ gốc: 1C24TUV/00000077 | AS68: -50252655 | AT68: -4020212 | AU68: -54272867 | BB68: =IF(AND(ISNUMBER(Z68),COUNT(AG68,AM68,AS68,AY68)=3),Z68+SUM(AG68,AM68,AS68,AY68),"") -> 0 | BC68: =IF(AND(ISNUMBER(AA68),COUNT(AH68,AN68,AT68,AZ68)=3),AA68+SUM(AH68,AN68,AT68,AZ68),"") -> 0 | BD68: =IF(AND(ISNUMBER(AB68),COUNT(AI68,AO68,AU68,BA68)=3),AB68+SUM(AI68,AO68,AU68,BA68),"") -> 0
A69: 1C24TUV | B69: {=INDEX('HD cty 2024'!B:B,MATCH('F0, F1, F2, ...'!$C69,'HD cty 2024'!B:B,0))} -> #N/A | C69: 79 | D69: 45352 | E69: 21006407 | F69: 1680513 | G69: 22686920 | H69: 1C25TUV | I69: 00001055 | J69: 45803 | K69: 1438963 | L69: 115117 | M69: 1554080 | Z69: 22445370 | AA69: 1795630 | AB69: 24241000 | AD69: Đảo khoản 1C25TUV/00001055; tham chiếu gốc 1C24TUV/00000079 | AG69: -1438963 | AH69: -115117 | AI69: -1554080 | AJ69: Giảm toàn bộ gốc: 1C24TUV/00000079 | AM69: -21006407 | AN69: -1680513 | AO69: -22686920 | BB69: =IF(AND(ISNUMBER(Z69),COUNT(AG69,AM69,AS69,AY69)=2),Z69+SUM(AG69,AM69,AS69,AY69),"") -> 0 | BC69: =IF(AND(ISNUMBER(AA69),COUNT(AH69,AN69,AT69,AZ69)=2),AA69+SUM(AH69,AN69,AT69,AZ69),"") -> 0 | BD69: =IF(AND(ISNUMBER(AB69),COUNT(AI69,AO69,AU69,BA69)=2),AB69+SUM(AI69,AO69,AU69,BA69),"") -> 0
A70: 1C24TUV | B70: {=INDEX('HD cty 2024'!B:B,MATCH('F0, F1, F2, ...'!$C70,'HD cty 2024'!B:B,0))} -> #N/A | C70: 81 | D70: 45352 | E70: 2196955 | F70: 175756 | G70: 2372711 | H70: 1C25TUV | I70: 00002318 | J70: 45807 | K70: -48822 | L70: -3906 | M70: -52728 | Z70: 2148133 | AA70: 171850 | AB70: 2319983 | AD70: Đảo khoản 1C25TUV/00002318; tham chiếu gốc 1C24TUV/00000081 | AG70: 48822 | AH70: 3906 | AI70: 52728 | AJ70: Giảm toàn bộ gốc: 1C24TUV/00000081 | AM70: -2196955 | AN70: -175756 | AO70: -2372711 | BB70: =IF(AND(ISNUMBER(Z70),COUNT(AG70,AM70,AS70,AY70)=2),Z70+SUM(AG70,AM70,AS70,AY70),"") -> 0 | BC70: =IF(AND(ISNUMBER(AA70),COUNT(AH70,AN70,AT70,AZ70)=2),AA70+SUM(AH70,AN70,AT70,AZ70),"") -> 0 | BD70: =IF(AND(ISNUMBER(AB70),COUNT(AI70,AO70,AU70,BA70)=2),AB70+SUM(AI70,AO70,AU70,BA70),"") -> 0
...

Sheet Ngoai le
A1: Thông tin người mua | C1: F0 — Hóa đơn gốc | I1: F1 — Hóa đơn liên quan | O1: F2 — Hóa đơn liên quan | U1: Giá trị cộng dồn và kiểm tra
A2: Tên người mua | B2: MST/CCCD chủ hộ nguyên bản | C2: Ký hiệu | D2: Số hóa đơn | E2: Ngày | F2: Tiền hàng | G2: Thuế | H2: Thanh toán | I2: Ký hiệu sửa 1 | J2: Số hóa đơn sửa 1 | K2: Ngày sửa 1 | L2: Tiền hàng sửa 1 | M2: Thuế sửa 1 | N2: Thanh toán sửa 1 | O2: Ký hiệu sửa 2 | P2: Số hóa đơn sửa 2 | Q2: Ngày sửa 2 | R2: Tiền hàng sửa 2 | S2: Thuế sửa 2 | T2: Thanh toán sửa 2 | U2: Cộng dồn tiền hàng | V2: Cộng dồn thuế | W2: Cộng dồn thanh toán | X2: Cần kiểm tra
A3: CÔNG TY TNHH GIA SƯ ETEACHER | B3: 0314215951 | C3: 1C24TUV | D3: 1 | E3: 45300 | F3: 1464200 | G3: 117136 | H3: 1581336 | U3: 1464200 | V3: 117136 | W3: 1581336
A4: CÔNG TY TNHH QUỐC TẾ SYNEX | B4: 0316328904 | C4: 1C24TUV | D4: 2 | E4: 45300 | F4: 2870093 | G4: 229607 | H4: 3099700 | U4: 2870093 | V4: 229607 | W4: 3099700
A5: CÔNG TY TNHH ĐẦU TƯ VÀ THIẾT KẾ XÂY DỰNG K.E.C | B5: 0318152318 | C5: 1C24TUV | D5: 21 | E5: 45308 | F5: 2546296 | G5: 203704 | H5: 2750000 | U5: 2546296 | V5: 203704 | W5: 2750000
A6: CÔNG TY TNHH THIẾT BỊ CÔNG NGHỆ QUỐC ANH | B6: 0107470865 | C6: 1C24TUV | D6: 22 | E6: 45315 | F6: 1793889 | G6: 143511 | H6: 1937400 | U6: 1793889 | V6: 143511 | W6: 1937400
A7: CÔNG TY TNHH THƯƠNG MẠI DỊCH VỤ GIA DỤNG THANH VÂN | B7: 0318074892 | C7: 1C24TUV | D7: 23 | E7: 45315 | F7: 3099556 | G7: 247964 | H7: 3347520 | I7: 1C25TUV | J7: 00000787 | K7: 45801 | L7: 422666 | M7: 33813 | N7: 456479 | U7: 3522222 | V7: 281777 | W7: 3803999
A8: CÔNG TY BẢO HIỂM PVI PHÍA NAM | B8: 0105402531-025 | C8: 1C24TUV | D8: 28 | E8: 45318 | F8: 2282500 | G8: 182600 | H8: 2465100 | I8: 1C25TUV | J8: 00000790 | K8: 45801 | L8: 253611 | M8: 20289 | N8: 273900 | U8: 2536111 | V8: 202889 | W8: 2739000
A9: CÔNG TY CỔ PHẦN XÂY DỰNG VÀ NỘI THẤT PHÚ MINH | B9: 0106357063 | C9: 1C24TUV | D9: 60 | E9: 45328 | F9: 2320785 | G9: 185663 | H9: 2506448 | I9: 1C24TUV | J9: 00000061 | K9: 45328 | L9: 2383944 | M9: 190716 | N9: 2574660 | O9: 1C25TUV | P9: 00002605 | Q9: 45808 | R9: 2536111 | S9: 202889 | T9: 2739000 | U9: 2536111 | V9: 202889 | W9: 2739000 | X9: 1C24TUV/00000060 có bản thay thế trong kỳ; không cộng bản bị thay thế; 1C24TUV/00000061 có bản thay thế trong kỳ; không cộng bản bị thay thế
A10: CÔNG TY CỔ PHẦN DỊCH VỤ LOGISTICS DẦU KHÍ VIỆT NAM | B10: 0311523789 | C10: 1C24TUV | D10: 62 | E10: 45342 | F10: 2462963 | G10: 197037 | H10: 2660000 | U10: 2462963 | V10: 197037 | W10: 2660000
A11: CÔNG TY CỔ PHẦN DỊCH VỤ LOGISTICS DẦU KHÍ VIỆT NAM | B11: 0311523789 | C11: 1C24TUV | D11: 63 | E11: 45342 | F11: 0 | G11: 0 | U11: 0 | V11: 0 | X11: 1C24TUV/00000063 có ô tiền bảng tổng trống; không tự điền 0
A12: CÔNG TY TNHH CƠ KHÍ XÂY DỰNG ANH ĐẠT | B12: 0310367287 | C12: 1C24TUV | D12: 64 | E12: 45350 | F12: 2407407 | G12: 192593 | H12: 2600000 | I12: 1C25TUV | J12: 00002609 | K12: 45808 | L12: -482407 | M12: -38593 | N12: -521000 | O12: 1C25TUV | P12: 00009375 | Q12: 45838 | R12: 482407 | S12: 38593 | T12: 521000 | U12: 2407407 | V12: 192593 | W12: 2600000
A13: CÔNG TY TNHH SẢN XUẤT VÀ ĐẦU TƯ AKIA | B13: 0315793560 | C13: 1C24TUV | D13: 110 | E13: 45366 | F13: 1574074 | G13: 125926 | H13: 1700000 | U13: 1574074 | V13: 125926 | W13: 1700000
A14: CÔNG TY TNHH SẢN XUẤT VÀ ĐẦU TƯ AKIA | B14: 0315793560 | C14: 1C24TUV | D14: 111 | E14: 45366 | F14: 3888889 | G14: 311111 | H14: 4200000 | U14: 3888889 | V14: 311111 | W14: 4200000
A15: CÔNG TY TNHH SPECTOS ASIA | B15: 0102970529 | C15: 1C24TUV | D15: 112 | E15: 45370 | F15: 2554074 | G15: 204326 | H15: 2758400 | U15: 2554074 | V15: 204326 | W15: 2758400
A16: CÔNG TY TNHH SẢN XUẤT VÀ ĐẦU TƯ AKIA | B16: 0315793560 | C16: 1C24TUV | D16: 113 | E16: 45371 | F16: 1851852 | G16: 148148 | H16: 2000000 | U16: 1851852 | V16: 148148 | W16: 2000000
A17: CÔNG TY TNHH THƯƠNG MẠI SẢN XUẤT XÂY DỰNG VÀ XUẤT NHẬP KHẨU GỖ KHÁNH THY | B17: 0317658951 | C17: 1C24TUV | D17: 122 | E17: 45379 | F17: 811111 | G17: 64889 | H17: 876000 | I17: 1C25TUV | J17: 00002611 | K17: 45808 | L17: 76852 | M17: 6148 | N17: 83000 | O17: 1C25TUV | P17: 00009436 | Q17: 45838 | R17: -76852 | S17: -6148 | T17: -83000 | U17: 811111 | V17: 64889 | W17: 876000
A18: CÔNG TY CỔ PHẦN ĐẦU TƯ XÂY DỰNG SOL E&C | B18: 0313541575 | C18: 1C24TUV | D18: 123 | E18: 45379 | F18: 1462037 | G18: 116963 | H18: 1579000 | I18: 1C25TUV | J18: 00001160 | K18: 45803 | L18: 370370 | M18: 29630 | N18: 400000 | U18: 1832407 | V18: 146593 | W18: 1979000
A19: CHI NHÁNH CÔNG TY TNHH MỘT THÀNH VIÊN KHÁCH SẠN AZUMAYA | B19: 0309489918-003 | C19: 1C24TUV | D19: 124 | E19: 45381 | F19: 4444444 | G19: 355556 | H19: 4800000 | U19: 4444444 | V19: 355556 | W19: 4800000
A20: CHI NHÁNH THÁI VĂN LUNG 2 - CÔNG TY TNHH MỘT THÀNH VIÊN KHÁCH SẠN AZUMAYA | B20: 0309489918-006 | C20: 1C24TUV | D20: 125 | E20: 45381 | F20: 10370370 | G20: 829630 | H20: 11200000 | U20: 10370370 | V20: 829630 | W20: 11200000
A21: CHI NHÁNH THÁI VĂN LUNG 2 - CÔNG TY TNHH MỘT THÀNH VIÊN KHÁCH SẠN AZUMAYA | B21: 0309489918-006 | C21: 1C24TUV | D21: 127 | E21: 45382 | F21: 8888889 | G21: 711111 | H21: 9600000 | U21: 8888889 | V21: 711111 | W21: 9600000
A22: CÔNG TY TNHH MỘT THÀNH VIÊN KHÁCH SẠN AZUMAYA | B22: 0309489918 | C22: 1C24TUV | D22: 132 | E22: 45387 | F22: 16296296 | G22: 1303704 | H22: 17600000 | U22: 16296296 | V22: 1303704 | W22: 17600000
A23: CÔNG TY TNHH MỘT THÀNH VIÊN KHÁCH SẠN AZUMAYA | B23: 0309489918 | C23: 1C24TUV | D23: 135 | E23: 45388 | F23: 10555556 | G23: 844444 | H23: 11400000 | U23: 10555556 | V23: 844444 | W23: 11400000
A24: CÔNG TY TNHH NHIÊN HOUSE | B24: 0316160754 | C24: 1C24TUV | D24: 162 | E24: 45391 | F24: 1151111 | G24: 92089 | H24: 1243200 | I24: 1C25TUV | J24: 00001223 | K24: 45804 | L24: 493333 | M24: 39467 | N24: 532800 | U24: 1644444 | V24: 131556 | W24: 1776000
A25: CÔNG TY CỔ PHẦN NTQ SOLUTION | B25: 0105355296 | C25: 1C24TUV | D25: 163 | E25: 45391 | F25: 1229556 | G25: 98364 | H25: 1327920 | U25: 1229556 | V25: 98364 | W25: 1327920
A26: CÔNG TY CỔ PHẦN MAJOR EDUCATION | B26: 0310596706 | C26: 1C24TUV | D26: 164 | E26: 45392 | F26: 1795370 | G26: 143630 | H26: 1939000 | U26: 1795370 | V26: 143630 | W26: 1939000
A27: HỘ KINH DOANH CỬA HÀNG DỤNG CỤ Y TẾ KHÁNH VIỄN | B27: 8127675505-001 | C27: 1C24TUV | D27: 169 | E27: 45397 | F27: 13430556 | G27: 1074444 | H27: 14505000 | U27: 13430556 | V27: 1074444 | W27: 14505000
A28: CÔNG TY TNHH THỔ KIM PHÁT | B28: 0110490847 | C28: 1C24TUV | D28: 170 | E28: 45402 | F28: 2420370 | G28: 193630 | H28: 2614000 | I28: 1C25TUV | J28: 00002615 | K28: 45808 | L28: 41667 | M28: 3333 | N28: 45000 | U28: 2462037 | V28: 196963 | W28: 2659000
A29: CÔNG TY CỔ PHẦN QUẢNG CÁO VÀ THƯƠNG MẠI GSOLUTION | B29: 0311950572 | C29: 1C24TUV | D29: 175 | E29: 45404 | F29: 78703704 | G29: 6296296 | H29: 85000000 | U29: 78703704 | V29: 6296296 | W29: 85000000
A30: CÔNG TY TNHH DRACO LOGISTICS VIỆT NAM | B30: 0318228694 | C30: 1C24TUV | D30: 183 | E30: 45407 | F30: 1600926 | G30: 128074 | H30: 1729000 | I30: 1C25TUV | J30: 00002616 | K30: 45808 | L30: 69444 | M30: 5556 | N30: 75000 | U30: 1670370 | V30: 133630 | W30: 1804000
A31: CÔNG TY TNHH MỘT THÀNH VIÊN THƯƠNG MẠI TƯ VẤN XÂY DỰNG MỸ HÒA | B31: 1702245926 | C31: 1C24TUV | D31: 185 | E31: 45408 | F31: 29274044 | G31: 2341924 | H31: 31615968 | U31: 29274044 | V31: 2341924 | W31: 31615968
